Workbook

Sheet S1_26_JUIL
A1: S1 — 26/07 AU 26/07/2026 — STANDARD 0 H
A2: ID ZK | B2: Nom | C2: Prénom | D2: Département | E2: Catégorie MOI/MOD | F2: Dim. 26/07 | G2: Heures standard (h) | H2: Travail total (h) | I2: Heures normales (h) | J2: HS 75% (h) | K2: HS 100% (h) | L2: ABS | M2: Congé payé (j) — seulement « Congé » | N2: Jour férié (j) | O2: Total (h) | P2: Contrôle
A3: 0025 | B3: JABNOUN | C3: MOUNA | D3: 01. Direction | E3: MOI | F3: Repos | G3: 0 | H3: =SUM(F3:F3)*24 -> 0 | I3: =SUM(F3:F3)*24 -> 0 | J3: 0 | K3: 0 | L3: =COUNTIF(F3:F3,"ABS") -> 0 | M3: =COUNTIF(F3:F3,"Congé") -> 0 | N3: =COUNTIF(F3:F3,"Férié") -> 0 | O3: =I3+J3+K3+(N3*8.5) -> 0 | P3: =IF(COUNTIF(F3:F3,"STC")>0,"STC",IF(IFERROR(ISNUMBER(SEARCH("!",F3)),FALSE),"À vérifier","OK")) -> OK
A4: 0081 | B4: LAKHEL | C4: MOHAMED | D4: 01. Direction | E4: MOI | F4: Repos | G4: 0 | H4: =SUM(F4:F4)*24 -> 0 | I4: =SUM(F4:F4)*24 -> 0 | J4: 0 | K4: 0 | L4: =COUNTIF(F4:F4,"ABS") -> 0 | M4: =COUNTIF(F4:F4,"Congé") -> 0 | N4: =COUNTIF(F4:F4,"Férié") -> 0 | O4: =I4+J4+K4+(N4*8.5) -> 0 | P4: =IF(COUNTIF(F4:F4,"STC")>0,"STC",IF(IFERROR(ISNUMBER(SEARCH("!",F4)),FALSE),"À vérifier","OK")) -> OK
A5: 0019 | B5: TRIMECHE | C5: CHAIMA | D5: 01. Direction | E5: MOI | F5: Repos | G5: 0 | H5: =SUM(F5:F5)*24 -> 0 | I5: =SUM(F5:F5)*24 -> 0 | J5: 0 | K5: 0 | L5: =COUNTIF(F5:F5,"ABS") -> 0 | M5: =COUNTIF(F5:F5,"Congé") -> 0 | N5: =COUNTIF(F5:F5,"Férié") -> 0 | O5: =I5+J5+K5+(N5*8.5) -> 0 | P5: =IF(COUNTIF(F5:F5,"STC")>0,"STC",IF(IFERROR(ISNUMBER(SEARCH("!",F5)),FALSE),"À vérifier","OK")) -> OK
A6: 124 | B6: AKKARI | C6: FAROUK | D6: 02. Production | E6: MOI | F6: Repos | G6: 0 | H6: =SUM(F6:F6)*24 -> 0 | I6: =SUM(F6:F6)*24 -> 0 | J6: 0 | K6: 0 | L6: =COUNTIF(F6:F6,"ABS") -> 0 | M6: =COUNTIF(F6:F6,"Congé") -> 0 | N6: =COUNTIF(F6:F6,"Férié") -> 0 | O6: =I6+J6+K6+(N6*8.5) -> 0 | P6: =IF(COUNTIF(F6:F6,"STC")>0,"STC",IF(IFERROR(ISNUMBER(SEARCH("!",F6)),FALSE),"À vérifier","OK")) -> OK
A7: 0022 | B7: AMAMOU | C7: ALI | D7: 02. Production | E7: MOI | F7: Repos | G7: 0 | H7: =SUM(F7:F7)*24 -> 0 | I7: =SUM(F7:F7)*24 -> 0 | J7: 0 | K7: 0 | L7: =COUNTIF(F7:F7,"ABS") -> 0 | M7: =COUNTIF(F7:F7,"Congé") -> 0 | N7: =COUNTIF(F7:F7,"Férié") -> 0 | O7: =I7+J7+K7+(N7*8.5) -> 0 | P7: =IF(COUNTIF(F7:F7,"STC")>0,"STC",IF(IFERROR(ISNUMBER(SEARCH("!",F7)),FALSE),"À vérifier","OK")) -> OK
A8: 0013 | B8: DHIBI | C8: TAOUFIK | D8: 02. Production | E8: MOI | F8: Repos | G8: 0 | H8: =SUM(F8:F8)*24 -> 0 | I8: =SUM(F8:F8)*24 -> 0 | J8: 0 | K8: 0 | L8: =COUNTIF(F8:F8,"ABS") -> 0 | M8: =COUNTIF(F8:F8,"Congé") -> 0 | N8: =COUNTIF(F8:F8,"Férié") -> 0 | O8: =I8+J8+K8+(N8*8.5) -> 0 | P8: =IF(COUNTIF(F8:F8,"STC")>0,"STC",IF(IFERROR(ISNUMBER(SEARCH("!",F8)),FALSE),"À vérifier","OK")) -> OK
A9: 0016 | B9: EZZEDINI | C9: HASSEN | D9: 02. Production | E9: MOI | F9: Repos | G9: 0 | H9: =SUM(F9:F9)*24 -> 0 | I9: =SUM(F9:F9)*24 -> 0 | J9: 0 | K9: 0 | L9: =COUNTIF(F9:F9,"ABS") -> 0 | M9: =COUNTIF(F9:F9,"Congé") -> 0 | N9: =COUNTIF(F9:F9,"Férié") -> 0 | O9: =I9+J9+K9+(N9*8.5) -> 0 | P9: =IF(COUNTIF(F9:F9,"STC")>0,"STC",IF(IFERROR(ISNUMBER(SEARCH("!",F9)),FALSE),"À vérifier","OK")) -> OK
A10: 0017 | B10: FERJANI | C10: MOKHLES | D10: 02. Production | E10: MOI | F10: Repos | G10: 0 | H10: =SUM(F10:F10)*24 -> 0 | I10: =SUM(F10:F10)*24 -> 0 | J10: 0 | K10: 0 | L10: =COUNTIF(F10:F10,"ABS") -> 0 | M10: =COUNTIF(F10:F10,"Congé") -> 0 | N10: =COUNTIF(F10:F10,"Férié") -> 0 | O10: =I10+J10+K10+(N10*8.5) -> 0 | P10: =IF(COUNTIF(F10:F10,"STC")>0,"STC",IF(IFERROR(ISNUMBER(SEARCH("!",F10)),FALSE),"À vérifier","OK")) -> OK
A11: 0023 | B11: TLILI | C11: ABDELMAJID | D11: 02. Production | E11: MOI | F11: Repos | G11: 0 | H11: =SUM(F11:F11)*24 -> 0 | I11: =SUM(F11:F11)*24 -> 0 | J11: 0 | K11: 0 | L11: =COUNTIF(F11:F11,"ABS") -> 0 | M11: =COUNTIF(F11:F11,"Congé") -> 0 | N11: =COUNTIF(F11:F11,"Férié") -> 0 | O11: =I11+J11+K11+(N11*8.5) -> 0 | P11: =IF(COUNTIF(F11:F11,"STC")>0,"STC",IF(IFERROR(ISNUMBER(SEARCH("!",F11)),FALSE),"À vérifier","OK")) -> OK
A12: 0029 | B12: CHAIMA | C12: MASSOUDI | D12: 03. Qualité | E12: MOI | F12: Repos | G12: 0 | H12: =SUM(F12:F12)*24 -> 0 | I12: =SUM(F12:F12)*24 -> 0 | J12: 0 | K12: 0 | L12: =COUNTIF(F12:F12,"ABS") -> 0 | M12: =COUNTIF(F12:F12,"Congé") -> 0 | N12: =COUNTIF(F12:F12,"Férié") -> 0 | O12: =I12+J12+K12+(N12*8.5) -> 0 | P12: =IF(COUNTIF(F12:F12,"STC")>0,"STC",IF(IFERROR(ISNUMBER(SEARCH("!",F12)),FALSE),"À vérifier","OK")) -> OK
A13: 132 | B13: GHARSALLAH | C13: RAWYA | D13: 03. Qualité | E13: MOI | F13: Repos | G13: 0 | H13: =SUM(F13:F13)*24 -> 0 | I13: =SUM(F13:F13)*24 -> 0 | J13: 0 | K13: 0 | L13: =COUNTIF(F13:F13,"ABS") -> 0 | M13: =COUNTIF(F13:F13,"Congé") -> 0 | N13: =COUNTIF(F13:F13,"Férié") -> 0 | O13: =I13+J13+K13+(N13*8.5) -> 0 | P13: =IF(COUNTIF(F13:F13,"STC")>0,"STC",IF(IFERROR(ISNUMBER(SEARCH("!",F13)),FALSE),"À vérifier","OK")) -> OK
A14: 174 | B14: HAMAD | C14: MOURAD | D14: 03. Qualité | E14: MOI | F14: Repos | G14: 0 | H14: =SUM(F14:F14)*24 -> 0 | I14: =SUM(F14:F14)*24 -> 0 | J14: 0 | K14: 0 | L14: =COUNTIF(F14:F14,"ABS") -> 0 | M14: =COUNTIF(F14:F14,"Congé") -> 0 | N14: =COUNTIF(F14:F14,"Férié") -> 0 | O14: =I14+J14+K14+(N14*8.5) -> 0 | P14: =IF(COUNTIF(F14:F14,"STC")>0,"STC",IF(IFERROR(ISNUMBER(SEARCH("!",F14)),FALSE),"À vérifier","OK")) -> OK
A15: 0003 | B15: JEDDA | C15: SAFA | D15: 03. Qualité | E15: MOI | F15: Repos | G15: 0 | H15: =SUM(F15:F15)*24 -> 0 | I15: =SUM(F15:F15)*24 -> 0 | J15: 0 | K15: 0 | L15: =COUNTIF(F15:F15,"ABS") -> 0 | M15: =COUNTIF(F15:F15,"Congé") -> 0 | N15: =COUNTIF(F15:F15,"Férié") -> 0 | O15: =I15+J15+K15+(N15*8.5) -> 0 | P15: =IF(COUNTIF(F15:F15,"STC")>0,"STC",IF(IFERROR(ISNUMBER(SEARCH("!",F15)),FALSE),"À vérifier","OK")) -> OK
A16: 0197 | B16: SAIDI | C16: SANA | D16: 03. Qualité | E16: MOI | F16: Repos | G16: 0 | H16: =SUM(F16:F16)*24 -> 0 | I16: =SUM(F16:F16)*24 -> 0 | J16: 0 | K16: 0 | L16: =COUNTIF(F16:F16,"ABS") -> 0 | M16: =COUNTIF(F16:F16,"Congé") -> 0 | N16: =COUNTIF(F16:F16,"Férié") -> 0 | O16: =I16+J16+K16+(N16*8.5) -> 0 | P16: =IF(COUNTIF(F16:F16,"STC")>0,"STC",IF(IFERROR(ISNUMBER(SEARCH("!",F16)),FALSE),"À vérifier","OK")) -> OK
A17: 0198 | B17: SAIDI | C17: SONIA | D17: 03. Qualité | E17: MOI | F17: Repos | G17: 0 | H17: =SUM(F17:F17)*24 -> 0 | I17: =SUM(F17:F17)*24 -> 0 | J17: 0 | K17: 0 | L17: =COUNTIF(F17:F17,"ABS") -> 0 | M17: =COUNTIF(F17:F17,"Congé") -> 0 | N17: =COUNTIF(F17:F17,"Férié") -> 0 | O17: =I17+J17+K17+(N17*8.5) -> 0 | P17: =IF(COUNTIF(F17:F17,"STC")>0,"STC",IF(IFERROR(ISNUMBER(SEARCH("!",F17)),FALSE),"À vérifier","OK")) -> OK
A18: 158 | B18: SEHLI | C18: EYA | D18: 03. Qualité | E18: MOI | F18: Repos | G18: 0 | H18: =SUM(F18:F18)*24 -> 0 | I18: =SUM(F18:F18)*24 -> 0 | J18: 0 | K18: 0 | L18: =COUNTIF(F18:F18,"ABS") -> 0 | M18: =COUNTIF(F18:F18,"Congé") -> 0 | N18: =COUNTIF(F18:F18,"Férié") -> 0 | O18: =I18+J18+K18+(N18*8.5) -> 0 | P18: =IF(COUNTIF(F18:F18,"STC")>0,"STC",IF(IFERROR(ISNUMBER(SEARCH("!",F18)),FALSE),"À vérifier","OK")) -> OK
A19: 0066 | B19: ZAAG | C19: NAOURES | D19: 03. Qualité | E19: MOI | F19: Repos | G19: 0 | H19: =SUM(F19:F19)*24 -> 0 | I19: =SUM(F19:F19)*24 -> 0 | J19: 0 | K19: 0 | L19: =COUNTIF(F19:F19,"ABS") -> 0 | M19: =COUNTIF(F19:F19,"Congé") -> 0 | N19: =COUNTIF(F19:F19,"Férié") -> 0 | O19: =I19+J19+K19+(N19*8.5) -> 0 | P19: =IF(COUNTIF(F19:F19,"STC")>0,"STC",IF(IFERROR(ISNUMBER(SEARCH("!",F19)),FALSE),"À vérifier","OK")) -> OK
A20: 0014 | B20: ABDENNOUR | C20: MOHAMED | D20: 04. Maintenance | E20: MOI | F20: Repos | G20: 0 | H20: =SUM(F20:F20)*24 -> 0 | I20: =SUM(F20:F20)*24 -> 0 | J20: 0 | K20: 0 | L20: =COUNTIF(F20:F20,"ABS") -> 0 | M20: =COUNTIF(F20:F20,"Congé") -> 0 | N20: =COUNTIF(F20:F20,"Férié") -> 0 | O20: =I20+J20+K20+(N20*8.5) -> 0 | P20: =IF(COUNTIF(F20:F20,"STC")>0,"STC",IF(IFERROR(ISNUMBER(SEARCH("!",F20)),FALSE),"À vérifier","OK")) -> OK
A21: 0024 | B21: DRIDI | C21: SLAH | D21: 04. Maintenance | E21: MOI | F21: Repos | G21: 0 | H21: =SUM(F21:F21)*24 -> 0 | I21: =SUM(F21:F21)*24 -> 0 | J21: 0 | K21: 0 | L21: =COUNTIF(F21:F21,"ABS") -> 0 | M21: =COUNTIF(F21:F21,"Congé") -> 0 | N21: =COUNTIF(F21:F21,"Férié") -> 0 | O21: =I21+J21+K21+(N21*8.5) -> 0 | P21: =IF(COUNTIF(F21:F21,"STC")>0,"STC",IF(IFERROR(ISNUMBER(SEARCH("!",F21)),FALSE),"À vérifier","OK")) -> OK
A22: 0140 | B22: FRIGUI | C22: KOUSSAY | D22: 04. Maintenance | E22: MOI | F22: Repos | G22: 0 | H22: =SUM(F22:F22)*24 -> 0 | I22: =SUM(F22:F22)*24 -> 0 | J22: 0 | K22: 0 | L22: =COUNTIF(F22:F22,"ABS") -> 0 | M22: =COUNTIF(F22:F22,"Congé") -> 0 | N22: =COUNTIF(F22:F22,"Férié") -> 0 | O22: =I22+J22+K22+(N22*8.5) -> 0 | P22: =IF(COUNTIF(F22:F22,"STC")>0,"STC",IF(IFERROR(ISNUMBER(SEARCH("!",F22)),FALSE),"À vérifier","OK")) -> OK
A23: 97 | B23: KHEDHER | C23: SALEM | D23: 04. Maintenance | E23: MOI | F23: Repos | G23: 0 | H23: =SUM(F23:F23)*24 -> 0 | I23: =SUM(F23:F23)*24 -> 0 | J23: 0 | K23: 0 | L23: =COUNTIF(F23:F23,"ABS") -> 0 | M23: =COUNTIF(F23:F23,"Congé") -> 0 | N23: =COUNTIF(F23:F23,"Férié") -> 0 | O23: =I23+J23+K23+(N23*8.5) -> 0 | P23: =IF(COUNTIF(F23:F23,"STC")>0,"STC",IF(IFERROR(ISNUMBER(SEARCH("!",F23)),FALSE),"À vérifier","OK")) -> OK
A24: 0020 | B24: LAAYOUNI | C24: ANOUAR | D24: 04. Maintenance | E24: MOI | F24: Repos | G24: 0 | H24: =SUM(F24:F24)*24 -> 0 | I24: =SUM(F24:F24)*24 -> 0 | J24: 0 | K24: 0 | L24: =COUNTIF(F24:F24,"ABS") -> 0 | M24: =COUNTIF(F24:F24,"Congé") -> 0 | N24: =COUNTIF(F24:F24,"Férié") -> 0 | O24: =I24+J24+K24+(N24*8.5) -> 0 | P24: =IF(COUNTIF(F24:F24,"STC")>0,"STC",IF(IFERROR(ISNUMBER(SEARCH("!",F24)),FALSE),"À vérifier","OK")) -> OK
A25: 0004 | B25: ZAIDI | C25: SEIFEDDINE | D25: 04. Maintenance | E25: MOI | F25: Repos | G25: 0 | H25: =SUM(F25:F25)*24 -> 0 | I25: =SUM(F25:F25)*24 -> 0 | J25: 0 | K25: 0 | L25: =COUNTIF(F25:F25,"ABS") -> 0 | M25: =COUNTIF(F25:F25,"Congé") -> 0 | N25: =COUNTIF(F25:F25,"Férié") -> 0 | O25: =I25+J25+K25+(N25*8.5) -> 0 | P25: =IF(COUNTIF(F25:F25,"STC")>0,"STC",IF(IFERROR(ISNUMBER(SEARCH("!",F25)),FALSE),"À vérifier","OK")) -> OK
A26: 0012 | B26: SOUSSI | C26: FATEN | D26: 05. Logistique | E26: MOI | F26: Repos | G26: 0 | H26: =SUM(F26:F26)*24 -> 0 | I26: =SUM(F26:F26)*24 -> 0 | J26: 0 | K26: 0 | L26: =COUNTIF(F26:F26,"ABS") -> 0 | M26: =COUNTIF(F26:F26,"Congé") -> 0 | N26: =COUNTIF(F26:F26,"Férié") -> 0 | O26: =I26+J26+K26+(N26*8.5) -> 0 | P26: =IF(COUNTIF(F26:F26,"STC")>0,"STC",IF(IFERROR(ISNUMBER(SEARCH("!",F26)),FALSE),"À vérifier","OK")) -> OK
A27: 249 | B27: WERFELLI | C27: OUSSEMA | D27: 05. Logistique | E27: MOI | F27: Repos | G27: 0 | H27: =SUM(F27:F27)*24 -> 0 | I27: =SUM(F27:F27)*24 -> 0 | J27: 0 | K27: 0 | L27: =COUNTIF(F27:F27,"ABS") -> 0 | M27: =COUNTIF(F27:F27,"Congé") -> 0 | N27: =COUNTIF(F27:F27,"Férié") -> 0 | O27: =I27+J27+K27+(N27*8.5) -> 0 | P27: =IF(COUNTIF(F27:F27,"STC")>0,"STC",IF(IFERROR(ISNUMBER(SEARCH("!",F27)),FALSE),"À vérifier","OK")) -> OK
A28: 135 | B28: ABID | C28: KHMAIS | D28: 06. RH | E28: MOI | F28: 0.33333333 | G28: 0 | H28: =SUM(F28:F28)*24 -> 8 | I28: =SUM(F28:F28)*24 -> 8 | J28: 0 | K28: 0 | L28: =COUNTIF(F28:F28,"ABS") -> 0 | M28: =COUNTIF(F28:F28,"Congé") -> 0 | N28: =COUNTIF(F28:F28,"Férié") -> 0 | O28: =I28+J28+K28+(N28*8.5) -> 8 | P28: =IF(COUNTIF(F28:F28,"STC")>0,"STC",IF(IFERROR(ISNUMBER(SEARCH("!",F28)),FALSE),"À vérifier","OK")) -> OK
A29: 0031 | B29: ALAYA | C29: ZOHRA | D29: 06. RH | E29: MOI | F29: Repos | G29: 0 | H29: =SUM(F29:F29)*24 -> 0 | I29: =SUM(F29:F29)*24 -> 0 | J29: 0 | K29: 0 | L29: =COUNTIF(F29:F29,"ABS") -> 0 | M29: =COUNTIF(F29:F29,"Congé") -> 0 | N29: =COUNTIF(F29:F29,"Férié") -> 0 | O29: =I29+J29+K29+(N29*8.5) -> 0 | P29: =IF(COUNTIF(F29:F29,"STC")>0,"STC",IF(IFERROR(ISNUMBER(SEARCH("!",F29)),FALSE),"À vérifier","OK")) -> OK
A30: 248 | B30: ATTIYA | C30: NAJEH | D30: 06. RH | E30: MOI | F30: Repos | G30: 0 | H30: =SUM(F30:F30)*24 -> 0 | I30: =SUM(F30:F30)*24 -> 0 | J30: 0 | K30: 0 | L30: =COUNTIF(F30:F30,"ABS") -> 0 | M30: =COUNTIF(F30:F30,"Congé") -> 0 | N30: =COUNTIF(F30:F30,"Férié") -> 0 | O30: =I30+J30+K30+(N30*8.5) -> 0 | P30: =IF(COUNTIF(F30:F30,"STC")>0,"STC",IF(IFERROR(ISNUMBER(SEARCH("!",F30)),FALSE),"À vérifier","OK")) -> OK
A31: 71 | B31: AZZEBI | C31: ATEF | D31: 06. RH | E31: MOI | F31: 0.33333333 | G31: 0 | H31: =SUM(F31:F31)*24 -> 8 | I31: =SUM(F31:F31)*24 -> 8 | J31: 0 | K31: 0 | L31: =COUNTIF(F31:F31,"ABS") -> 0 | M31: =COUNTIF(F31:F31,"Congé") -> 0 | N31: =COUNTIF(F31:F31,"Férié") -> 0 | O31: =I31+J31+K31+(N31*8.5) -> 8 | P31: =IF(COUNTIF(F31:F31,"STC")>0,"STC",IF(IFERROR(ISNUMBER(SEARCH("!",F31)),FALSE),"À vérifier","OK")) -> OK
A32: 227 | B32: BEN SAAD | C32: ZIED | D32: 06. RH | E32: MOI | F32: Repos | G32: 0 | H32: =SUM(F32:F32)*24 -> 0 | I32: =SUM(F32:F32)*24 -> 0 | J32: 0 | K32: 0 | L32: =COUNTIF(F32:F32,"ABS") -> 0 | M32: =COUNTIF(F32:F32,"Congé") -> 0 | N32: =COUNTIF(F32:F32,"Férié") -> 0 | O32: =I32+J32+K32+(N32*8.5) -> 0 | P32: =IF(COUNTIF(F32:F32,"STC")>0,"STC",IF(IFERROR(ISNUMBER(SEARCH("!",F32)),FALSE),"À vérifier","OK")) -> OK
A33: 251 | B33: BRAHEM | C33: WISSEM | D33: 06. RH | E33: MOI | F33: 0.33333333 | G33: 0 | H33: =SUM(F33:F33)*24 -> 8 | I33: =SUM(F33:F33)*24 -> 8 | J33: 0 | K33: 0 | L33: =COUNTIF(F33:F33,"ABS") -> 0 | M33: =COUNTIF(F33:F33,"Congé") -> 0 | N33: =COUNTIF(F33:F33,"Férié") -> 0 | O33: =I33+J33+K33+(N33*8.5) -> 8 | P33: =IF(COUNTIF(F33:F33,"STC")>0,"STC",IF(IFERROR(ISNUMBER(SEARCH("!",F33)),FALSE),"À vérifier","OK")) -> OK
A34: 70 | B34: BRAHIM | C34: HAMDI | D34: 06. RH | E34: MOI | F34: 0.33333333 | G34: 0 | H34: =SUM(F34:F34)*24 -> 8 | I34: =SUM(F34:F34)*24 -> 8 | J34: 0 | K34: 0 | L34: =COUNTIF(F34:F34,"ABS") -> 0 | M34: =COUNTIF(F34:F34,"Congé") -> 0 | N34: =COUNTIF(F34:F34,"Férié") -> 0 | O34: =I34+J34+K34+(N34*8.5) -> 8 | P34: =IF(COUNTIF(F34:F34,"STC")>0,"STC",IF(IFERROR(ISNUMBER(SEARCH("!",F34)),FALSE),"À vérifier","OK")) -> OK
A35: 50 | B35: CHOGHRANI | C35: HAYKEL | D35: 06. RH | E35: MOI | F35: Repos | G35: 0 | H35: =SUM(F35:F35)*24 -> 0 | I35: =SUM(F35:F35)*24 -> 0 | J35: 0 | K35: 0 | L35: =COUNTIF(F35:F35,"ABS") -> 0 | M35: =COUNTIF(F35:F35,"Congé") -> 0 | N35: =COUNTIF(F35:F35,"Férié") -> 0 | O35: =I35+J35+K35+(N35*8.5) -> 0 | P35: =IF(COUNTIF(F35:F35,"STC")>0,"STC",IF(IFERROR(ISNUMBER(SEARCH("!",F35)),FALSE),"À vérifier","OK")) -> OK
A36: 250 | B36: EL AYEB | C36: NAOURES | D36: 06. RH | E36: MOI | F36: Repos | G36: 0 | H36: =SUM(F36:F36)*24 -> 0 | I36: =SUM(F36:F36)*24 -> 0 | J36: 0 | K36: 0 | L36: =COUNTIF(F36:F36,"ABS") -> 0 | M36: =COUNTIF(F36:F36,"Congé") -> 0 | N36: =COUNTIF(F36:F36,"Férié") -> 0 | O36: =I36+J36+K36+(N36*8.5) -> 0 | P36: =IF(COUNTIF(F36:F36,"STC")>0,"STC",IF(IFERROR(ISNUMBER(SEARCH("!",F36)),FALSE),"À vérifier","OK")) -> OK
A37: 0006 | B37: ESSID | C37: HOUSSEM EDDINE | D37: 06. RH | E37: MOI | F37: 0.33333333 | G37: 0 | H37: =SUM(F37:F37)*24 -> 8 | I37: =SUM(F37:F37)*24 -> 8 | J37: 0 | K37: 0 | L37: =COUNTIF(F37:F37,"ABS") -> 0 | M37: =COUNTIF(F37:F37,"Congé") -> 0 | N37: =COUNTIF(F37:F37,"Férié") -> 0 | O37: =I37+J37+K37+(N37*8.5) -> 8 | P37: =IF(COUNTIF(F37:F37,"STC")>0,"STC",IF(IFERROR(ISNUMBER(SEARCH("!",F37)),FALSE),"À vérifier","OK")) -> OK
A38: 223 | B38: GUEDER | C38: AHLEM | D38: 06. RH | E38: MOI | F38: Repos | G38: 0 | H38: =SUM(F38:F38)*24 -> 0 | I38: =SUM(F38:F38)*24 -> 0 | J38: 0 | K38: 0 | L38: =COUNTIF(F38:F38,"ABS") -> 0 | M38: =COUNTIF(F38:F38,"Congé") -> 0 | N38: =COUNTIF(F38:F38,"Férié") -> 0 | O38: =I38+J38+K38+(N38*8.5) -> 0 | P38: =IF(COUNTIF(F38:F38,"STC")>0,"STC",IF(IFERROR(ISNUMBER(SEARCH("!",F38)),FALSE),"À vérifier","OK")) -> OK
A39: 0100 | B39: MLAIKIA | C39: JAWAHER | D39: 06. RH | E39: MOI | F39: Repos | G39: 0 | H39: =SUM(F39:F39)*24 -> 0 | I39: =SUM(F39:F39)*24 -> 0 | J39: 0 | K39: 0 | L39: =COUNTIF(F39:F39,"ABS") -> 0 | M39: =COUNTIF(F39:F39,"Congé") -> 0 | N39: =COUNTIF(F39:F39,"Férié") -> 0 | O39: =I39+J39+K39+(N39*8.5) -> 0 | P39: =IF(COUNTIF(F39:F39,"STC")>0,"STC",IF(IFERROR(ISNUMBER(SEARCH("!",F39)),FALSE),"À vérifier","OK")) -> OK
A40: 0010 | B40: RTIBI | C40: MOKHTAR | D40: 06. RH | E40: MOI | F40: Repos | G40: 0 | H40: =SUM(F40:F40)*24 -> 0 | I40: =SUM(F40:F40)*24 -> 0 | J40: 0 | K40: 0 | L40: =COUNTIF(F40:F40,"ABS") -> 0 | M40: =COUNTIF(F40:F40,"Congé") -> 0 | N40: =COUNTIF(F40:F40,"Férié") -> 0 | O40: =I40+J40+K40+(N40*8.5) -> 0 | P40: =IF(COUNTIF(F40:F40,"STC")>0,"STC",IF(IFERROR(ISNUMBER(SEARCH("!",F40)),FALSE),"À vérifier","OK")) -> OK
...

Sheet S2_27_JUIL-02_AOUT
A1: S2 — 27/07 AU 02/08/2026 — STANDARD 48 H
A2: ID ZK | B2: Nom | C2: Prénom | D2: Département | E2: Catégorie MOI/MOD | F2: Lun. 27/07 | G2: Mar. 28/07 | H2: Mer. 29/07 | I2: Jeu. 30/07 | J2: Ven. 31/07 | K2: Sam. 01/08 | L2: Dim. 02/08 | M2: Heures standard (h) | N2: Travail total (h) | O2: Heures normales (h) | P2: HS 75% (h) | Q2: HS 100% (h) | R2: ABS | S2: Congé payé (j) — seulement « Congé » | T2: Jour férié (j) | U2: Total (h) | V2: Contrôle
A3: 50 | B3: CHOGHRANI | C3: HAYKEL | D3: 06. RH | E3: MOI | F3: 0.33333333 | G3: 0.33333333 | H3: 0.33333333 | I3: 0.3125 | J3: 0.41666667 | K3: repos | L3: repos | M3: =48 -> 48 | N3: =SUM(F3:L3)*24 -> 41.5 | O3: =IF(COUNTIF(PARAMETRES_REGIMES!$A$3:$A$100,$A3)>0,MIN(M3,SUM(F3:L3)*24),MIN(M3,SUM(F3:K3)*24)) -> 41.5 | P3: =IF(COUNTIF(PARAMETRES_REGIMES!$A$3:$A$100,$A3)>0,FLOOR(MAX(SUM(F3:L3)*24-M3,0),0.5),FLOOR(MAX(SUM(F3:K3)*24-M3,0),0.5)) -> 0 | Q3: =IF(COUNTIF(PARAMETRES_REGIMES!$A$3:$A$100,$A3)>0,0,IF(ISNUMBER(L3),FLOOR(MAX(L3*24,0),0.5),0)) -> 0 | R3: =COUNTIF(F3:L3,"ABS") -> 0 | S3: =COUNTIF(F3:L3,"Congé")+COUNTIF(F3:L3,"CSS")*0+COUNTIF(F3:L3,"CM")*0 -> 0 | T3: =COUNTIF(F3:L3,"Férié") -> 0 | U3: =O3+P3+Q3+(T3*8.5) -> 41.5 | V3: =IF(COUNTIF(F3:L3,"STC")>0,"STC",IF(OR(IFERROR(ISNUMBER(SEARCH("!",F3)),FALSE),IFERROR(ISNUMBER(SEARCH("!",G3)),FALSE),IFERROR(ISNUMBER(SEARCH("!",H3)),FALSE),IFERROR(ISNUMBER(SEARCH("!",I3)),FALSE),IFERROR(ISNUMBER(SEARCH("!",J3)),FALSE),IFERROR(ISNUMBER(SEARCH("!",K3)),FALSE),IFERROR(ISNUMBER(SEARCH("!",L3)),FALSE)),"À vérifier","OK")) -> OK
A4: 53 | B4: ALLEGUI | C4: AMEL | D4: 02. Production | E4: MOD | F4: ABS | G4: 0.3125 | H4: 0.39583333 | I4: 0.39583333 | J4: 0.375 | K4: repos | L4: repos | M4: =48 -> 48 | N4: =SUM(F4:L4)*24 -> 35.5 | O4: =IF(COUNTIF(PARAMETRES_REGIMES!$A$3:$A$100,$A4)>0,MIN(M4,SUM(F4:L4)*24),MIN(M4,SUM(F4:K4)*24)) -> 35.5 | P4: =IF(COUNTIF(PARAMETRES_REGIMES!$A$3:$A$100,$A4)>0,FLOOR(MAX(SUM(F4:L4)*24-M4,0),0.5),FLOOR(MAX(SUM(F4:K4)*24-M4,0),0.5)) -> 0 | Q4: =IF(COUNTIF(PARAMETRES_REGIMES!$A$3:$A$100,$A4)>0,0,IF(ISNUMBER(L4),FLOOR(MAX(L4*24,0),0.5),0)) -> 0 | R4: =COUNTIF(F4:L4,"ABS") -> 1 | S4: =COUNTIF(F4:L4,"Congé")+COUNTIF(F4:L4,"CSS")*0+COUNTIF(F4:L4,"CM")*0 -> 0 | T4: =COUNTIF(F4:L4,"Férié") -> 0 | U4: =O4+P4+Q4+(T4*8.5) -> 35.5 | V4: =IF(COUNTIF(F4:L4,"STC")>0,"STC",IF(OR(IFERROR(ISNUMBER(SEARCH("!",F4)),FALSE),IFERROR(ISNUMBER(SEARCH("!",G4)),FALSE),IFERROR(ISNUMBER(SEARCH("!",H4)),FALSE),IFERROR(ISNUMBER(SEARCH("!",I4)),FALSE),IFERROR(ISNUMBER(SEARCH("!",J4)),FALSE),IFERROR(ISNUMBER(SEARCH("!",K4)),FALSE),IFERROR(ISNUMBER(SEARCH("!",L4)),FALSE)),"À vérifier","OK")) -> OK
A5: 70 | B5: BRAHIM | C5: HAMDI | D5: 06. RH | E5: MOI | F5: 0.33333333 | G5: 0.33333333 | H5: 0.33333333 | I5: 0.33333333 | J5: 0.33333333 | K5: repos | L5: repos | M5: =48 -> 48 | N5: =SUM(F5:L5)*24 -> 40 | O5: =IF(COUNTIF(PARAMETRES_REGIMES!$A$3:$A$100,$A5)>0,MIN(M5,SUM(F5:L5)*24),MIN(M5,SUM(F5:K5)*24)) -> 40 | P5: =IF(COUNTIF(PARAMETRES_REGIMES!$A$3:$A$100,$A5)>0,FLOOR(MAX(SUM(F5:L5)*24-M5,0),0.5),FLOOR(MAX(SUM(F5:K5)*24-M5,0),0.5)) -> 0 | Q5: =IF(COUNTIF(PARAMETRES_REGIMES!$A$3:$A$100,$A5)>0,0,IF(ISNUMBER(L5),FLOOR(MAX(L5*24,0),0.5),0)) -> 0 | R5: =COUNTIF(F5:L5,"ABS") -> 0 | S5: =COUNTIF(F5:L5,"Congé")+COUNTIF(F5:L5,"CSS")*0+COUNTIF(F5:L5,"CM")*0 -> 0 | T5: =COUNTIF(F5:L5,"Férié") -> 0 | U5: =O5+P5+Q5+(T5*8.5) -> 40 | V5: =IF(COUNTIF(F5:L5,"STC")>0,"STC",IF(OR(IFERROR(ISNUMBER(SEARCH("!",F5)),FALSE),IFERROR(ISNUMBER(SEARCH("!",G5)),FALSE),IFERROR(ISNUMBER(SEARCH("!",H5)),FALSE),IFERROR(ISNUMBER(SEARCH("!",I5)),FALSE),IFERROR(ISNUMBER(SEARCH("!",J5)),FALSE),IFERROR(ISNUMBER(SEARCH("!",K5)),FALSE),IFERROR(ISNUMBER(SEARCH("!",L5)),FALSE)),"À vérifier","OK")) -> OK
A6: 71 | B6: AZZEBI | C6: ATEF | D6: 06. RH | E6: MOI | F6: 0.33333333 | G6: 0.33333333 | H6: Repos | I6: 0.33333333 | J6: 0.33333333 | K6: repos | L6: repos | M6: =48 -> 48 | N6: =SUM(F6:L6)*24 -> 32 | O6: =IF(COUNTIF(PARAMETRES_REGIMES!$A$3:$A$100,$A6)>0,MIN(M6,SUM(F6:L6)*24),MIN(M6,SUM(F6:K6)*24)) -> 32 | P6: =IF(COUNTIF(PARAMETRES_REGIMES!$A$3:$A$100,$A6)>0,FLOOR(MAX(SUM(F6:L6)*24-M6,0),0.5),FLOOR(MAX(SUM(F6:K6)*24-M6,0),0.5)) -> 0 | Q6: =IF(COUNTIF(PARAMETRES_REGIMES!$A$3:$A$100,$A6)>0,0,IF(ISNUMBER(L6),FLOOR(MAX(L6*24,0),0.5),0)) -> 0 | R6: =COUNTIF(F6:L6,"ABS") -> 0 | S6: =COUNTIF(F6:L6,"Congé")+COUNTIF(F6:L6,"CSS")*0+COUNTIF(F6:L6,"CM")*0 -> 0 | T6: =COUNTIF(F6:L6,"Férié") -> 0 | U6: =O6+P6+Q6+(T6*8.5) -> 32 | V6: =IF(COUNTIF(F6:L6,"STC")>0,"STC",IF(OR(IFERROR(ISNUMBER(SEARCH("!",F6)),FALSE),IFERROR(ISNUMBER(SEARCH("!",G6)),FALSE),IFERROR(ISNUMBER(SEARCH("!",H6)),FALSE),IFERROR(ISNUMBER(SEARCH("!",I6)),FALSE),IFERROR(ISNUMBER(SEARCH("!",J6)),FALSE),IFERROR(ISNUMBER(SEARCH("!",K6)),FALSE),IFERROR(ISNUMBER(SEARCH("!",L6)),FALSE)),"À vérifier","OK")) -> OK
A7: 89 | B7: MANNAI | C7: SAMI | D7: 04. Maintenance | E7: MOD | F7: 0.3125 | G7: 0.33333333 | H7: 0.39583333 | I7: 0.39583333 | J7: 0.39583333 | K7: repos | L7: repos | M7: =48 -> 48 | N7: =SUM(F7:L7)*24 -> 44 | O7: =IF(COUNTIF(PARAMETRES_REGIMES!$A$3:$A$100,$A7)>0,MIN(M7,SUM(F7:L7)*24),MIN(M7,SUM(F7:K7)*24)) -> 44 | P7: =IF(COUNTIF(PARAMETRES_REGIMES!$A$3:$A$100,$A7)>0,FLOOR(MAX(SUM(F7:L7)*24-M7,0),0.5),FLOOR(MAX(SUM(F7:K7)*24-M7,0),0.5)) -> 0 | Q7: =IF(COUNTIF(PARAMETRES_REGIMES!$A$3:$A$100,$A7)>0,0,IF(ISNUMBER(L7),FLOOR(MAX(L7*24,0),0.5),0)) -> 0 | R7: =COUNTIF(F7:L7,"ABS") -> 0 | S7: =COUNTIF(F7:L7,"Congé")+COUNTIF(F7:L7,"CSS")*0+COUNTIF(F7:L7,"CM")*0 -> 0 | T7: =COUNTIF(F7:L7,"Férié") -> 0 | U7: =O7+P7+Q7+(T7*8.5) -> 44 | V7: =IF(COUNTIF(F7:L7,"STC")>0,"STC",IF(OR(IFERROR(ISNUMBER(SEARCH("!",F7)),FALSE),IFERROR(ISNUMBER(SEARCH("!",G7)),FALSE),IFERROR(ISNUMBER(SEARCH("!",H7)),FALSE),IFERROR(ISNUMBER(SEARCH("!",I7)),FALSE),IFERROR(ISNUMBER(SEARCH("!",J7)),FALSE),IFERROR(ISNUMBER(SEARCH("!",K7)),FALSE),IFERROR(ISNUMBER(SEARCH("!",L7)),FALSE)),"À vérifier","OK")) -> OK
A8: 94 | B8: RJEYBI | C8: AMAL | D8: 02. Production | E8: MOD | F8: 0.3125 | G8: 0.3125 | H8: 0.39583333 | I8: ABS | J8: 0.33333333 | K8: repos | L8: repos | M8: =48 -> 48 | N8: =SUM(F8:L8)*24 -> 32.5 | O8: =IF(COUNTIF(PARAMETRES_REGIMES!$A$3:$A$100,$A8)>0,MIN(M8,SUM(F8:L8)*24),MIN(M8,SUM(F8:K8)*24)) -> 32.5 | P8: =IF(COUNTIF(PARAMETRES_REGIMES!$A$3:$A$100,$A8)>0,FLOOR(MAX(SUM(F8:L8)*24-M8,0),0.5),FLOOR(MAX(SUM(F8:K8)*24-M8,0),0.5)) -> 0 | Q8: =IF(COUNTIF(PARAMETRES_REGIMES!$A$3:$A$100,$A8)>0,0,IF(ISNUMBER(L8),FLOOR(MAX(L8*24,0),0.5),0)) -> 0 | R8: =COUNTIF(F8:L8,"ABS") -> 1 | S8: =COUNTIF(F8:L8,"Congé")+COUNTIF(F8:L8,"CSS")*0+COUNTIF(F8:L8,"CM")*0 -> 0 | T8: =COUNTIF(F8:L8,"Férié") -> 0 | U8: =O8+P8+Q8+(T8*8.5) -> 32.5 | V8: =IF(COUNTIF(F8:L8,"STC")>0,"STC",IF(OR(IFERROR(ISNUMBER(SEARCH("!",F8)),FALSE),IFERROR(ISNUMBER(SEARCH("!",G8)),FALSE),IFERROR(ISNUMBER(SEARCH("!",H8)),FALSE),IFERROR(ISNUMBER(SEARCH("!",I8)),FALSE),IFERROR(ISNUMBER(SEARCH("!",J8)),FALSE),IFERROR(ISNUMBER(SEARCH("!",K8)),FALSE),IFERROR(ISNUMBER(SEARCH("!",L8)),FALSE)),"À vérifier","OK")) -> OK
A9: 96 | B9: LADJIMI | C9: FRADJ | D9: 02. Production | E9: MOD | F9: 0.39583333 | G9: ABS | H9: 0.3125 | I9: 0.39583333 | J9: 0.39583333 | K9: repos | L9: repos | M9: =48 -> 48 | N9: =SUM(F9:L9)*24 -> 36 | O9: =IF(COUNTIF(PARAMETRES_REGIMES!$A$3:$A$100,$A9)>0,MIN(M9,SUM(F9:L9)*24),MIN(M9,SUM(F9:K9)*24)) -> 36 | P9: =IF(COUNTIF(PARAMETRES_REGIMES!$A$3:$A$100,$A9)>0,FLOOR(MAX(SUM(F9:L9)*24-M9,0),0.5),FLOOR(MAX(SUM(F9:K9)*24-M9,0),0.5)) -> 0 | Q9: =IF(COUNTIF(PARAMETRES_REGIMES!$A$3:$A$100,$A9)>0,0,IF(ISNUMBER(L9),FLOOR(MAX(L9*24,0),0.5),0)) -> 0 | R9: =COUNTIF(F9:L9,"ABS") -> 1 | S9: =COUNTIF(F9:L9,"Congé")+COUNTIF(F9:L9,"CSS")*0+COUNTIF(F9:L9,"CM")*0 -> 0 | T9: =COUNTIF(F9:L9,"Férié") -> 0 | U9: =O9+P9+Q9+(T9*8.5) -> 36 | V9: =IF(COUNTIF(F9:L9,"STC")>0,"STC",IF(OR(IFERROR(ISNUMBER(SEARCH("!",F9)),FALSE),IFERROR(ISNUMBER(SEARCH("!",G9)),FALSE),IFERROR(ISNUMBER(SEARCH("!",H9)),FALSE),IFERROR(ISNUMBER(SEARCH("!",I9)),FALSE),IFERROR(ISNUMBER(SEARCH("!",J9)),FALSE),IFERROR(ISNUMBER(SEARCH("!",K9)),FALSE),IFERROR(ISNUMBER(SEARCH("!",L9)),FALSE)),"À vérifier","OK")) -> OK
A10: 97 | B10: KHEDHER | C10: SALEM | D10: 04. Maintenance | E10: MOI | F10: ABS | G10: ABS | H10: ABS | I10: 0.39583333 | J10: ABS | K10: repos | L10: repos | M10: =48 -> 48 | N10: =SUM(F10:L10)*24 -> 9.5 | O10: =IF(COUNTIF(PARAMETRES_REGIMES!$A$3:$A$100,$A10)>0,MIN(M10,SUM(F10:L10)*24),MIN(M10,SUM(F10:K10)*24)) -> 9.5 | P10: =IF(COUNTIF(PARAMETRES_REGIMES!$A$3:$A$100,$A10)>0,FLOOR(MAX(SUM(F10:L10)*24-M10,0),0.5),FLOOR(MAX(SUM(F10:K10)*24-M10,0),0.5)) -> 0 | Q10: =IF(COUNTIF(PARAMETRES_REGIMES!$A$3:$A$100,$A10)>0,0,IF(ISNUMBER(L10),FLOOR(MAX(L10*24,0),0.5),0)) -> 0 | R10: =COUNTIF(F10:L10,"ABS") -> 4 | S10: =COUNTIF(F10:L10,"Congé")+COUNTIF(F10:L10,"CSS")*0+COUNTIF(F10:L10,"CM")*0 -> 0 | T10: =COUNTIF(F10:L10,"Férié") -> 0 | U10: =O10+P10+Q10+(T10*8.5) -> 9.5 | V10: =IF(COUNTIF(F10:L10,"STC")>0,"STC",IF(OR(IFERROR(ISNUMBER(SEARCH("!",F10)),FALSE),IFERROR(ISNUMBER(SEARCH("!",G10)),FALSE),IFERROR(ISNUMBER(SEARCH("!",H10)),FALSE),IFERROR(ISNUMBER(SEARCH("!",I10)),FALSE),IFERROR(ISNUMBER(SEARCH("!",J10)),FALSE),IFERROR(ISNUMBER(SEARCH("!",K10)),FALSE),IFERROR(ISNUMBER(SEARCH("!",L10)),FALSE)),"À vérifier","OK")) -> OK
A11: 118 | B11: KHMISSI | C11: ASMA | D11: 02. Production | E11: MOD | F11: 0.3125 | G11: 0.3125 | H11: 0.39583333 | I11: 0.375 | J11: 0.39583333 | K11: repos | L11: repos | M11: =48 -> 48 | N11: =SUM(F11:L11)*24 -> 43 | O11: =IF(COUNTIF(PARAMETRES_REGIMES!$A$3:$A$100,$A11)>0,MIN(M11,SUM(F11:L11)*24),MIN(M11,SUM(F11:K11)*24)) -> 43 | P11: =IF(COUNTIF(PARAMETRES_REGIMES!$A$3:$A$100,$A11)>0,FLOOR(MAX(SUM(F11:L11)*24-M11,0),0.5),FLOOR(MAX(SUM(F11:K11)*24-M11,0),0.5)) -> 0 | Q11: =IF(COUNTIF(PARAMETRES_REGIMES!$A$3:$A$100,$A11)>0,0,IF(ISNUMBER(L11),FLOOR(MAX(L11*24,0),0.5),0)) -> 0 | R11: =COUNTIF(F11:L11,"ABS") -> 0 | S11: =COUNTIF(F11:L11,"Congé")+COUNTIF(F11:L11,"CSS")*0+COUNTIF(F11:L11,"CM")*0 -> 0 | T11: =COUNTIF(F11:L11,"Férié") -> 0 | U11: =O11+P11+Q11+(T11*8.5) -> 43 | V11: =IF(COUNTIF(F11:L11,"STC")>0,"STC",IF(OR(IFERROR(ISNUMBER(SEARCH("!",F11)),FALSE),IFERROR(ISNUMBER(SEARCH("!",G11)),FALSE),IFERROR(ISNUMBER(SEARCH("!",H11)),FALSE),IFERROR(ISNUMBER(SEARCH("!",I11)),FALSE),IFERROR(ISNUMBER(SEARCH("!",J11)),FALSE),IFERROR(ISNUMBER(SEARCH("!",K11)),FALSE),IFERROR(ISNUMBER(SEARCH("!",L11)),FALSE)),"À vérifier","OK")) -> OK
A12: 124 | B12: AKKARI | C12: FAROUK | D12: 02. Production | E12: MOI | F12: 0.375 | G12: 0.39583333 | H12: 0.39583333 | I12: 0.39583333 | J12: 0.35416667 | K12: repos | L12: repos | M12: =48 -> 48 | N12: =SUM(F12:L12)*24 -> 46 | O12: =IF(COUNTIF(PARAMETRES_REGIMES!$A$3:$A$100,$A12)>0,MIN(M12,SUM(F12:L12)*24),MIN(M12,SUM(F12:K12)*24)) -> 46 | P12: =IF(COUNTIF(PARAMETRES_REGIMES!$A$3:$A$100,$A12)>0,FLOOR(MAX(SUM(F12:L12)*24-M12,0),0.5),FLOOR(MAX(SUM(F12:K12)*24-M12,0),0.5)) -> 0 | Q12: =IF(COUNTIF(PARAMETRES_REGIMES!$A$3:$A$100,$A12)>0,0,IF(ISNUMBER(L12),FLOOR(MAX(L12*24,0),0.5),0)) -> 0 | R12: =COUNTIF(F12:L12,"ABS") -> 0 | S12: =COUNTIF(F12:L12,"Congé")+COUNTIF(F12:L12,"CSS")*0+COUNTIF(F12:L12,"CM")*0 -> 0 | T12: =COUNTIF(F12:L12,"Férié") -> 0 | U12: =O12+P12+Q12+(T12*8.5) -> 46 | V12: =IF(COUNTIF(F12:L12,"STC")>0,"STC",IF(OR(IFERROR(ISNUMBER(SEARCH("!",F12)),FALSE),IFERROR(ISNUMBER(SEARCH("!",G12)),FALSE),IFERROR(ISNUMBER(SEARCH("!",H12)),FALSE),IFERROR(ISNUMBER(SEARCH("!",I12)),FALSE),IFERROR(ISNUMBER(SEARCH("!",J12)),FALSE),IFERROR(ISNUMBER(SEARCH("!",K12)),FALSE),IFERROR(ISNUMBER(SEARCH("!",L12)),FALSE)),"À vérifier","OK")) -> OK
A13: 132 | B13: GHARSALLAH | C13: RAWYA | D13: 03. Qualité | E13: MOI | F13: 0.39583333 | G13: ABS | H13: 0.39583333 | I13: 0.39583333 | J13: ABS | K13: repos | L13: repos | M13: =48 -> 48 | N13: =SUM(F13:L13)*24 -> 28.5 | O13: =IF(COUNTIF(PARAMETRES_REGIMES!$A$3:$A$100,$A13)>0,MIN(M13,SUM(F13:L13)*24),MIN(M13,SUM(F13:K13)*24)) -> 28.5 | P13: =IF(COUNTIF(PARAMETRES_REGIMES!$A$3:$A$100,$A13)>0,FLOOR(MAX(SUM(F13:L13)*24-M13,0),0.5),FLOOR(MAX(SUM(F13:K13)*24-M13,0),0.5)) -> 0 | Q13: =IF(COUNTIF(PARAMETRES_REGIMES!$A$3:$A$100,$A13)>0,0,IF(ISNUMBER(L13),FLOOR(MAX(L13*24,0),0.5),0)) -> 0 | R13: =COUNTIF(F13:L13,"ABS") -> 2 | S13: =COUNTIF(F13:L13,"Congé")+COUNTIF(F13:L13,"CSS")*0+COUNTIF(F13:L13,"CM")*0 -> 0 | T13: =COUNTIF(F13:L13,"Férié") -> 0 | U13: =O13+P13+Q13+(T13*8.5) -> 28.5 | V13: =IF(COUNTIF(F13:L13,"STC")>0,"STC",IF(OR(IFERROR(ISNUMBER(SEARCH("!",F13)),FALSE),IFERROR(ISNUMBER(SEARCH("!",G13)),FALSE),IFERROR(ISNUMBER(SEARCH("!",H13)),FALSE),IFERROR(ISNUMBER(SEARCH("!",I13)),FALSE),IFERROR(ISNUMBER(SEARCH("!",J13)),FALSE),IFERROR(ISNUMBER(SEARCH("!",K13)),FALSE),IFERROR(ISNUMBER(SEARCH("!",L13)),FALSE)),"À vérifier","OK")) -> OK
A14: 135 | B14: ABID | C14: KHMAIS | D14: 06. RH | E14: MOI | F14: 0.3125 | G14: 0.3125 | H14: 0.3125 | I14: 0.3125 | J14: ABS | K14: repos | L14: repos | M14: =48 -> 48 | N14: =SUM(F14:L14)*24 -> 30 | O14: =IF(COUNTIF(PARAMETRES_REGIMES!$A$3:$A$100,$A14)>0,MIN(M14,SUM(F14:L14)*24),MIN(M14,SUM(F14:K14)*24)) -> 30 | P14: =IF(COUNTIF(PARAMETRES_REGIMES!$A$3:$A$100,$A14)>0,FLOOR(MAX(SUM(F14:L14)*24-M14,0),0.5),FLOOR(MAX(SUM(F14:K14)*24-M14,0),0.5)) -> 0 | Q14: =IF(COUNTIF(PARAMETRES_REGIMES!$A$3:$A$100,$A14)>0,0,IF(ISNUMBER(L14),FLOOR(MAX(L14*24,0),0.5),0)) -> 0 | R14: =COUNTIF(F14:L14,"ABS") -> 1 | S14: =COUNTIF(F14:L14,"Congé")+COUNTIF(F14:L14,"CSS")*0+COUNTIF(F14:L14,"CM")*0 -> 0 | T14: =COUNTIF(F14:L14,"Férié") -> 0 | U14: =O14+P14+Q14+(T14*8.5) -> 30 | V14: =IF(COUNTIF(F14:L14,"STC")>0,"STC",IF(OR(IFERROR(ISNUMBER(SEARCH("!",F14)),FALSE),IFERROR(ISNUMBER(SEARCH("!",G14)),FALSE),IFERROR(ISNUMBER(SEARCH("!",H14)),FALSE),IFERROR(ISNUMBER(SEARCH("!",I14)),FALSE),IFERROR(ISNUMBER(SEARCH("!",J14)),FALSE),IFERROR(ISNUMBER(SEARCH("!",K14)),FALSE),IFERROR(ISNUMBER(SEARCH("!",L14)),FALSE)),"À vérifier","OK")) -> OK
A15: 158 | B15: SEHLI | C15: EYA | D15: 03. Qualité | E15: MOI | F15: 0.22916667 | G15: 0.39583333 | H15: 0.39583333 | I15: 0.39583333 | J15: 0.39583333 | K15: repos | L15: repos | M15: =48 -> 48 | N15: =SUM(F15:L15)*24 -> 43.5 | O15: =IF(COUNTIF(PARAMETRES_REGIMES!$A$3:$A$100,$A15)>0,MIN(M15,SUM(F15:L15)*24),MIN(M15,SUM(F15:K15)*24)) -> 43.5 | P15: =IF(COUNTIF(PARAMETRES_REGIMES!$A$3:$A$100,$A15)>0,FLOOR(MAX(SUM(F15:L15)*24-M15,0),0.5),FLOOR(MAX(SUM(F15:K15)*24-M15,0),0.5)) -> 0 | Q15: =IF(COUNTIF(PARAMETRES_REGIMES!$A$3:$A$100,$A15)>0,0,IF(ISNUMBER(L15),FLOOR(MAX(L15*24,0),0.5),0)) -> 0 | R15: =COUNTIF(F15:L15,"ABS") -> 0 | S15: =COUNTIF(F15:L15,"Congé")+COUNTIF(F15:L15,"CSS")*0+COUNTIF(F15:L15,"CM")*0 -> 0 | T15: =COUNTIF(F15:L15,"Férié") -> 0 | U15: =O15+P15+Q15+(T15*8.5) -> 43.5 | V15: =IF(COUNTIF(F15:L15,"STC")>0,"STC",IF(OR(IFERROR(ISNUMBER(SEARCH("!",F15)),FALSE),IFERROR(ISNUMBER(SEARCH("!",G15)),FALSE),IFERROR(ISNUMBER(SEARCH("!",H15)),FALSE),IFERROR(ISNUMBER(SEARCH("!",I15)),FALSE),IFERROR(ISNUMBER(SEARCH("!",J15)),FALSE),IFERROR(ISNUMBER(SEARCH("!",K15)),FALSE),IFERROR(ISNUMBER(SEARCH("!",L15)),FALSE)),"À vérifier","OK")) -> OK
A16: 163 | B16: BOUYATTAY | C16: SENDA | D16: 02. Production | E16: MOD | F16: 0.39583333 | G16: 0.39583333 | H16: 0.39583333 | I16: 0.39583333 | J16: 0.39583333 | K16: repos | L16: repos | M16: =48 -> 48 | N16: =SUM(F16:L16)*24 -> 47.5 | O16: =IF(COUNTIF(PARAMETRES_REGIMES!$A$3:$A$100,$A16)>0,MIN(M16,SUM(F16:L16)*24),MIN(M16,SUM(F16:K16)*24)) -> 47.5 | P16: =IF(COUNTIF(PARAMETRES_REGIMES!$A$3:$A$100,$A16)>0,FLOOR(MAX(SUM(F16:L16)*24-M16,0),0.5),FLOOR(MAX(SUM(F16:K16)*24-M16,0),0.5)) -> 0 | Q16: =IF(COUNTIF(PARAMETRES_REGIMES!$A$3:$A$100,$A16)>0,0,IF(ISNUMBER(L16),FLOOR(MAX(L16*24,0),0.5),0)) -> 0 | R16: =COUNTIF(F16:L16,"ABS") -> 0 | S16: =COUNTIF(F16:L16,"Congé")+COUNTIF(F16:L16,"CSS")*0+COUNTIF(F16:L16,"CM")*0 -> 0 | T16: =COUNTIF(F16:L16,"Férié") -> 0 | U16: =O16+P16+Q16+(T16*8.5) -> 47.5 | V16: =IF(COUNTIF(F16:L16,"STC")>0,"STC",IF(OR(IFERROR(ISNUMBER(SEARCH("!",F16)),FALSE),IFERROR(ISNUMBER(SEARCH("!",G16)),FALSE),IFERROR(ISNUMBER(SEARCH("!",H16)),FALSE),IFERROR(ISNUMBER(SEARCH("!",I16)),FALSE),IFERROR(ISNUMBER(SEARCH("!",J16)),FALSE),IFERROR(ISNUMBER(SEARCH("!",K16)),FALSE),IFERROR(ISNUMBER(SEARCH("!",L16)),FALSE)),"À vérifier","OK")) -> OK
A17: 166 | B17: GUEZMIL | C17: DOUAA | D17: 02. Production | E17: MOD | F17: 0.39583333 | G17: 0.39583333 | H17: 0.39583333 | I17: 0.39583333 | J17: 0.39583333 | K17: repos | L17: repos | M17: =48 -> 48 | N17: =SUM(F17:L17)*24 -> 47.5 | O17: =IF(COUNTIF(PARAMETRES_REGIMES!$A$3:$A$100,$A17)>0,MIN(M17,SUM(F17:L17)*24),MIN(M17,SUM(F17:K17)*24)) -> 47.5 | P17: =IF(COUNTIF(PARAMETRES_REGIMES!$A$3:$A$100,$A17)>0,FLOOR(MAX(SUM(F17:L17)*24-M17,0),0.5),FLOOR(MAX(SUM(F17:K17)*24-M17,0),0.5)) -> 0 | Q17: =IF(COUNTIF(PARAMETRES_REGIMES!$A$3:$A$100,$A17)>0,0,IF(ISNUMBER(L17),FLOOR(MAX(L17*24,0),0.5),0)) -> 0 | R17: =COUNTIF(F17:L17,"ABS") -> 0 | S17: =COUNTIF(F17:L17,"Congé")+COUNTIF(F17:L17,"CSS")*0+COUNTIF(F17:L17,"CM")*0 -> 0 | T17: =COUNTIF(F17:L17,"Férié") -> 0 | U17: =O17+P17+Q17+(T17*8.5) -> 47.5 | V17: =IF(COUNTIF(F17:L17,"STC")>0,"STC",IF(OR(IFERROR(ISNUMBER(SEARCH("!",F17)),FALSE),IFERROR(ISNUMBER(SEARCH("!",G17)),FALSE),IFERROR(ISNUMBER(SEARCH("!",H17)),FALSE),IFERROR(ISNUMBER(SEARCH("!",I17)),FALSE),IFERROR(ISNUMBER(SEARCH("!",J17)),FALSE),IFERROR(ISNUMBER(SEARCH("!",K17)),FALSE),IFERROR(ISNUMBER(SEARCH("!",L17)),FALSE)),"À vérifier","OK")) -> OK
A18: 169 | B18: EDWENI | C18: ONS | D18: 02. Production | E18: MOD | F18: ABS | G18: 0.3125 | H18: 0.39583333 | I18: 0.39583333 | J18: 0.39583333 | K18: repos | L18: repos | M18: =48 -> 48 | N18: =SUM(F18:L18)*24 -> 36 | O18: =IF(COUNTIF(PARAMETRES_REGIMES!$A$3:$A$100,$A18)>0,MIN(M18,SUM(F18:L18)*24),MIN(M18,SUM(F18:K18)*24)) -> 36 | P18: =IF(COUNTIF(PARAMETRES_REGIMES!$A$3:$A$100,$A18)>0,FLOOR(MAX(SUM(F18:L18)*24-M18,0),0.5),FLOOR(MAX(SUM(F18:K18)*24-M18,0),0.5)) -> 0 | Q18: =IF(COUNTIF(PARAMETRES_REGIMES!$A$3:$A$100,$A18)>0,0,IF(ISNUMBER(L18),FLOOR(MAX(L18*24,0),0.5),0)) -> 0 | R18: =COUNTIF(F18:L18,"ABS") -> 1 | S18: =COUNTIF(F18:L18,"Congé")+COUNTIF(F18:L18,"CSS")*0+COUNTIF(F18:L18,"CM")*0 -> 0 | T18: =COUNTIF(F18:L18,"Férié") -> 0 | U18: =O18+P18+Q18+(T18*8.5) -> 36 | V18: =IF(COUNTIF(F18:L18,"STC")>0,"STC",IF(OR(IFERROR(ISNUMBER(SEARCH("!",F18)),FALSE),IFERROR(ISNUMBER(SEARCH("!",G18)),FALSE),IFERROR(ISNUMBER(SEARCH("!",H18)),FALSE),IFERROR(ISNUMBER(SEARCH("!",I18)),FALSE),IFERROR(ISNUMBER(SEARCH("!",J18)),FALSE),IFERROR(ISNUMBER(SEARCH("!",K18)),FALSE),IFERROR(ISNUMBER(SEARCH("!",L18)),FALSE)),"À vérifier","OK")) -> OK
A19: 174 | B19: HAMAD | C19: MOURAD | D19: 03. Qualité | E19: MOI | F19: 0.39583333 | G19: 0.39583333 | H19: 0.39583333 | I19: 0.39583333 | J19: 0.39583333 | K19: repos | L19: repos | M19: =48 -> 48 | N19: =SUM(F19:L19)*24 -> 47.5 | O19: =IF(COUNTIF(PARAMETRES_REGIMES!$A$3:$A$100,$A19)>0,MIN(M19,SUM(F19:L19)*24),MIN(M19,SUM(F19:K19)*24)) -> 47.5 | P19: =IF(COUNTIF(PARAMETRES_REGIMES!$A$3:$A$100,$A19)>0,FLOOR(MAX(SUM(F19:L19)*24-M19,0),0.5),FLOOR(MAX(SUM(F19:K19)*24-M19,0),0.5)) -> 0 | Q19: =IF(COUNTIF(PARAMETRES_REGIMES!$A$3:$A$100,$A19)>0,0,IF(ISNUMBER(L19),FLOOR(MAX(L19*24,0),0.5),0)) -> 0 | R19: =COUNTIF(F19:L19,"ABS") -> 0 | S19: =COUNTIF(F19:L19,"Congé")+COUNTIF(F19:L19,"CSS")*0+COUNTIF(F19:L19,"CM")*0 -> 0 | T19: =COUNTIF(F19:L19,"Férié") -> 0 | U19: =O19+P19+Q19+(T19*8.5) -> 47.5 | V19: =IF(COUNTIF(F19:L19,"STC")>0,"STC",IF(OR(IFERROR(ISNUMBER(SEARCH("!",F19)),FALSE),IFERROR(ISNUMBER(SEARCH("!",G19)),FALSE),IFERROR(ISNUMBER(SEARCH("!",H19)),FALSE),IFERROR(ISNUMBER(SEARCH("!",I19)),FALSE),IFERROR(ISNUMBER(SEARCH("!",J19)),FALSE),IFERROR(ISNUMBER(SEARCH("!",K19)),FALSE),IFERROR(ISNUMBER(SEARCH("!",L19)),FALSE)),"À vérifier","OK")) -> OK
A20: 177 | B20: BESSWA | C20: YASMINE | D20: 02. Production | E20: MOD | F20: 0.39583333 | G20: ABS | H20: ABS | I20: 0.3125 | J20: 0.39583333 | K20: repos | L20: repos | M20: =48 -> 48 | N20: =SUM(F20:L20)*24 -> 26.5 | O20: =IF(COUNTIF(PARAMETRES_REGIMES!$A$3:$A$100,$A20)>0,MIN(M20,SUM(F20:L20)*24),MIN(M20,SUM(F20:K20)*24)) -> 26.5 | P20: =IF(COUNTIF(PARAMETRES_REGIMES!$A$3:$A$100,$A20)>0,FLOOR(MAX(SUM(F20:L20)*24-M20,0),0.5),FLOOR(MAX(SUM(F20:K20)*24-M20,0),0.5)) -> 0 | Q20: =IF(COUNTIF(PARAMETRES_REGIMES!$A$3:$A$100,$A20)>0,0,IF(ISNUMBER(L20),FLOOR(MAX(L20*24,0),0.5),0)) -> 0 | R20: =COUNTIF(F20:L20,"ABS") -> 2 | S20: =COUNTIF(F20:L20,"Congé")+COUNTIF(F20:L20,"CSS")*0+COUNTIF(F20:L20,"CM")*0 -> 0 | T20: =COUNTIF(F20:L20,"Férié") -> 0 | U20: =O20+P20+Q20+(T20*8.5) -> 26.5 | V20: =IF(COUNTIF(F20:L20,"STC")>0,"STC",IF(OR(IFERROR(ISNUMBER(SEARCH("!",F20)),FALSE),IFERROR(ISNUMBER(SEARCH("!",G20)),FALSE),IFERROR(ISNUMBER(SEARCH("!",H20)),FALSE),IFERROR(ISNUMBER(SEARCH("!",I20)),FALSE),IFERROR(ISNUMBER(SEARCH("!",J20)),FALSE),IFERROR(ISNUMBER(SEARCH("!",K20)),FALSE),IFERROR(ISNUMBER(SEARCH("!",L20)),FALSE)),"À vérifier","OK")) -> OK
A21: 183 | B21: HRABI | C21: ISSA | D21: 02. Production | E21: MOD | F21: STC | G21: STC | H21: STC | I21: STC | J21: STC | K21: repos | L21: repos | M21: =48 -> 48 | N21: =SUM(F21:L21)*24 -> 0 | O21: =IF(COUNTIF(PARAMETRES_REGIMES!$A$3:$A$100,$A21)>0,MIN(M21,SUM(F21:L21)*24),MIN(M21,SUM(F21:K21)*24)) -> 0 | P21: =IF(COUNTIF(PARAMETRES_REGIMES!$A$3:$A$100,$A21)>0,FLOOR(MAX(SUM(F21:L21)*24-M21,0),0.5),FLOOR(MAX(SUM(F21:K21)*24-M21,0),0.5)) -> 0 | Q21: =IF(COUNTIF(PARAMETRES_REGIMES!$A$3:$A$100,$A21)>0,0,IF(ISNUMBER(L21),FLOOR(MAX(L21*24,0),0.5),0)) -> 0 | R21: =COUNTIF(F21:L21,"ABS") -> 0 | S21: =COUNTIF(F21:L21,"Congé")+COUNTIF(F21:L21,"CSS")*0+COUNTIF(F21:L21,"CM")*0 -> 0 | T21: =COUNTIF(F21:L21,"Férié") -> 0 | U21: =O21+P21+Q21+(T21*8.5) -> 0 | V21: =IF(COUNTIF(F21:L21,"STC")>0,"STC",IF(OR(IFERROR(ISNUMBER(SEARCH("!",F21)),FALSE),IFERROR(ISNUMBER(SEARCH("!",G21)),FALSE),IFERROR(ISNUMBER(SEARCH("!",H21)),FALSE),IFERROR(ISNUMBER(SEARCH("!",I21)),FALSE),IFERROR(ISNUMBER(SEARCH("!",J21)),FALSE),IFERROR(ISNUMBER(SEARCH("!",K21)),FALSE),IFERROR(ISNUMBER(SEARCH("!",L21)),FALSE)),"À vérifier","OK")) -> STC
A22: 192 | B22: CHIBA | C22: RANIM | D22: 02. Production | E22: MOD | F22: ABS | G22: ABS | H22: 0.3125 | I22: 0.39583333 | J22: 0.39583333 | K22: repos | L22: repos | M22: =48 -> 48 | N22: =SUM(F22:L22)*24 -> 26.5 | O22: =IF(COUNTIF(PARAMETRES_REGIMES!$A$3:$A$100,$A22)>0,MIN(M22,SUM(F22:L22)*24),MIN(M22,SUM(F22:K22)*24)) -> 26.5 | P22: =IF(COUNTIF(PARAMETRES_REGIMES!$A$3:$A$100,$A22)>0,FLOOR(MAX(SUM(F22:L22)*24-M22,0),0.5),FLOOR(MAX(SUM(F22:K22)*24-M22,0),0.5)) -> 0 | Q22: =IF(COUNTIF(PARAMETRES_REGIMES!$A$3:$A$100,$A22)>0,0,IF(ISNUMBER(L22),FLOOR(MAX(L22*24,0),0.5),0)) -> 0 | R22: =COUNTIF(F22:L22,"ABS") -> 2 | S22: =COUNTIF(F22:L22,"Congé")+COUNTIF(F22:L22,"CSS")*0+COUNTIF(F22:L22,"CM")*0 -> 0 | T22: =COUNTIF(F22:L22,"Férié") -> 0 | U22: =O22+P22+Q22+(T22*8.5) -> 26.5 | V22: =IF(COUNTIF(F22:L22,"STC")>0,"STC",IF(OR(IFERROR(ISNUMBER(SEARCH("!",F22)),FALSE),IFERROR(ISNUMBER(SEARCH("!",G22)),FALSE),IFERROR(ISNUMBER(SEARCH("!",H22)),FALSE),IFERROR(ISNUMBER(SEARCH("!",I22)),FALSE),IFERROR(ISNUMBER(SEARCH("!",J22)),FALSE),IFERROR(ISNUMBER(SEARCH("!",K22)),FALSE),IFERROR(ISNUMBER(SEARCH("!",L22)),FALSE)),"À vérifier","OK")) -> OK
A23: 199 | B23: KLAII | C23: MARAM | D23: 02. Production | E23: MOD | F23: ABS | G23: 0.3125 | H23: 0.39583333 | I23: 0.39583333 | J23: 0.39583333 | K23: repos | L23: repos | M23: =48 -> 48 | N23: =SUM(F23:L23)*24 -> 36 | O23: =IF(COUNTIF(PARAMETRES_REGIMES!$A$3:$A$100,$A23)>0,MIN(M23,SUM(F23:L23)*24),MIN(M23,SUM(F23:K23)*24)) -> 36 | P23: =IF(COUNTIF(PARAMETRES_REGIMES!$A$3:$A$100,$A23)>0,FLOOR(MAX(SUM(F23:L23)*24-M23,0),0.5),FLOOR(MAX(SUM(F23:K23)*24-M23,0),0.5)) -> 0 | Q23: =IF(COUNTIF(PARAMETRES_REGIMES!$A$3:$A$100,$A23)>0,0,IF(ISNUMBER(L23),FLOOR(MAX(L23*24,0),0.5),0)) -> 0 | R23: =COUNTIF(F23:L23,"ABS") -> 1 | S23: =COUNTIF(F23:L23,"Congé")+COUNTIF(F23:L23,"CSS")*0+COUNTIF(F23:L23,"CM")*0 -> 0 | T23: =COUNTIF(F23:L23,"Férié") -> 0 | U23: =O23+P23+Q23+(T23*8.5) -> 36 | V23: =IF(COUNTIF(F23:L23,"STC")>0,"STC",IF(OR(IFERROR(ISNUMBER(SEARCH("!",F23)),FALSE),IFERROR(ISNUMBER(SEARCH("!",G23)),FALSE),IFERROR(ISNUMBER(SEARCH("!",H23)),FALSE),IFERROR(ISNUMBER(SEARCH("!",I23)),FALSE),IFERROR(ISNUMBER(SEARCH("!",J23)),FALSE),IFERROR(ISNUMBER(SEARCH("!",K23)),FALSE),IFERROR(ISNUMBER(SEARCH("!",L23)),FALSE)),"À vérifier","OK")) -> OK
A24: 204 | B24: ZAOUALI | C24: CHAYMA | D24: 02. Production | E24: MOD | F24: 0.39583333 | G24: 0.39583333 | H24: 0.39583333 | I24: 0.39583333 | J24: 0.39583333 | K24: repos | L24: repos | M24: =48 -> 48 | N24: =SUM(F24:L24)*24 -> 47.5 | O24: =IF(COUNTIF(PARAMETRES_REGIMES!$A$3:$A$100,$A24)>0,MIN(M24,SUM(F24:L24)*24),MIN(M24,SUM(F24:K24)*24)) -> 47.5 | P24: =IF(COUNTIF(PARAMETRES_REGIMES!$A$3:$A$100,$A24)>0,FLOOR(MAX(SUM(F24:L24)*24-M24,0),0.5),FLOOR(MAX(SUM(F24:K24)*24-M24,0),0.5)) -> 0 | Q24: =IF(COUNTIF(PARAMETRES_REGIMES!$A$3:$A$100,$A24)>0,0,IF(ISNUMBER(L24),FLOOR(MAX(L24*24,0),0.5),0)) -> 0 | R24: =COUNTIF(F24:L24,"ABS") -> 0 | S24: =COUNTIF(F24:L24,"Congé")+COUNTIF(F24:L24,"CSS")*0+COUNTIF(F24:L24,"CM")*0 -> 0 | T24: =COUNTIF(F24:L24,"Férié") -> 0 | U24: =O24+P24+Q24+(T24*8.5) -> 47.5 | V24: =IF(COUNTIF(F24:L24,"STC")>0,"STC",IF(OR(IFERROR(ISNUMBER(SEARCH("!",F24)),FALSE),IFERROR(ISNUMBER(SEARCH("!",G24)),FALSE),IFERROR(ISNUMBER(SEARCH("!",H24)),FALSE),IFERROR(ISNUMBER(SEARCH("!",I24)),FALSE),IFERROR(ISNUMBER(SEARCH("!",J24)),FALSE),IFERROR(ISNUMBER(SEARCH("!",K24)),FALSE),IFERROR(ISNUMBER(SEARCH("!",L24)),FALSE)),"À vérifier","OK")) -> OK
A25: 215 | B25: ZAIRI | C25: FADOUA | D25: 02. Production | E25: MOD | F25: 0.39583333 | G25: 0.39583333 | H25: 0.39583333 | I25: 0.39583333 | J25: 0.39583333 | K25: repos | L25: repos | M25: =48 -> 48 | N25: =SUM(F25:L25)*24 -> 47.5 | O25: =IF(COUNTIF(PARAMETRES_REGIMES!$A$3:$A$100,$A25)>0,MIN(M25,SUM(F25:L25)*24),MIN(M25,SUM(F25:K25)*24)) -> 47.5 | P25: =IF(COUNTIF(PARAMETRES_REGIMES!$A$3:$A$100,$A25)>0,FLOOR(MAX(SUM(F25:L25)*24-M25,0),0.5),FLOOR(MAX(SUM(F25:K25)*24-M25,0),0.5)) -> 0 | Q25: =IF(COUNTIF(PARAMETRES_REGIMES!$A$3:$A$100,$A25)>0,0,IF(ISNUMBER(L25),FLOOR(MAX(L25*24,0),0.5),0)) -> 0 | R25: =COUNTIF(F25:L25,"ABS") -> 0 | S25: =COUNTIF(F25:L25,"Congé")+COUNTIF(F25:L25,"CSS")*0+COUNTIF(F25:L25,"CM")*0 -> 0 | T25: =COUNTIF(F25:L25,"Férié") -> 0 | U25: =O25+P25+Q25+(T25*8.5) -> 47.5 | V25: =IF(COUNTIF(F25:L25,"STC")>0,"STC",IF(OR(IFERROR(ISNUMBER(SEARCH("!",F25)),FALSE),IFERROR(ISNUMBER(SEARCH("!",G25)),FALSE),IFERROR(ISNUMBER(SEARCH("!",H25)),FALSE),IFERROR(ISNUMBER(SEARCH("!",I25)),FALSE),IFERROR(ISNUMBER(SEARCH("!",J25)),FALSE),IFERROR(ISNUMBER(SEARCH("!",K25)),FALSE),IFERROR(ISNUMBER(SEARCH("!",L25)),FALSE)),"À vérifier","OK")) -> OK
A26: 223 | B26: GUEDER | C26: AHLEM | D26: 06. RH | E26: MOI | F26: 0.29166667 | G26: 0.375 | H26: ABS | I26: 0.375 | J26: 0.375 | K26: repos | L26: repos | M26: =48 -> 48 | N26: =SUM(F26:L26)*24 -> 34 | O26: =IF(COUNTIF(PARAMETRES_REGIMES!$A$3:$A$100,$A26)>0,MIN(M26,SUM(F26:L26)*24),MIN(M26,SUM(F26:K26)*24)) -> 34 | P26: =IF(COUNTIF(PARAMETRES_REGIMES!$A$3:$A$100,$A26)>0,FLOOR(MAX(SUM(F26:L26)*24-M26,0),0.5),FLOOR(MAX(SUM(F26:K26)*24-M26,0),0.5)) -> 0 | Q26: =IF(COUNTIF(PARAMETRES_REGIMES!$A$3:$A$100,$A26)>0,0,IF(ISNUMBER(L26),FLOOR(MAX(L26*24,0),0.5),0)) -> 0 | R26: =COUNTIF(F26:L26,"ABS") -> 1 | S26: =COUNTIF(F26:L26,"Congé")+COUNTIF(F26:L26,"CSS")*0+COUNTIF(F26:L26,"CM")*0 -> 0 | T26: =COUNTIF(F26:L26,"Férié") -> 0 | U26: =O26+P26+Q26+(T26*8.5) -> 34 | V26: =IF(COUNTIF(F26:L26,"STC")>0,"STC",IF(OR(IFERROR(ISNUMBER(SEARCH("!",F26)),FALSE),IFERROR(ISNUMBER(SEARCH("!",G26)),FALSE),IFERROR(ISNUMBER(SEARCH("!",H26)),FALSE),IFERROR(ISNUMBER(SEARCH("!",I26)),FALSE),IFERROR(ISNUMBER(SEARCH("!",J26)),FALSE),IFERROR(ISNUMBER(SEARCH("!",K26)),FALSE),IFERROR(ISNUMBER(SEARCH("!",L26)),FALSE)),"À vérifier","OK")) -> OK
A27: 227 | B27: BEN SAAD | C27: ZIED | D27: 06. RH | E27: MOI | F27: 0.33333333 | G27: ABS | H27: 0.33333333 | I27: 0.33333333 | J27: 0.27083333 | K27: repos | L27: repos | M27: =48 -> 48 | N27: =SUM(F27:L27)*24 -> 30.5 | O27: =IF(COUNTIF(PARAMETRES_REGIMES!$A$3:$A$100,$A27)>0,MIN(M27,SUM(F27:L27)*24),MIN(M27,SUM(F27:K27)*24)) -> 30.5 | P27: =IF(COUNTIF(PARAMETRES_REGIMES!$A$3:$A$100,$A27)>0,FLOOR(MAX(SUM(F27:L27)*24-M27,0),0.5),FLOOR(MAX(SUM(F27:K27)*24-M27,0),0.5)) -> 0 | Q27: =IF(COUNTIF(PARAMETRES_REGIMES!$A$3:$A$100,$A27)>0,0,IF(ISNUMBER(L27),FLOOR(MAX(L27*24,0),0.5),0)) -> 0 | R27: =COUNTIF(F27:L27,"ABS") -> 1 | S27: =COUNTIF(F27:L27,"Congé")+COUNTIF(F27:L27,"CSS")*0+COUNTIF(F27:L27,"CM")*0 -> 0 | T27: =COUNTIF(F27:L27,"Férié") -> 0 | U27: =O27+P27+Q27+(T27*8.5) -> 30.5 | V27: =IF(COUNTIF(F27:L27,"STC")>0,"STC",IF(OR(IFERROR(ISNUMBER(SEARCH("!",F27)),FALSE),IFERROR(ISNUMBER(SEARCH("!",G27)),FALSE),IFERROR(ISNUMBER(SEARCH("!",H27)),FALSE),IFERROR(ISNUMBER(SEARCH("!",I27)),FALSE),IFERROR(ISNUMBER(SEARCH("!",J27)),FALSE),IFERROR(ISNUMBER(SEARCH("!",K27)),FALSE),IFERROR(ISNUMBER(SEARCH("!",L27)),FALSE)),"À vérifier","OK")) -> OK
A28: 234 | B28: KACEM | C28: MALEK | D28: 02. Production | E28: MOD | F28: 0.33333333 | G28: 0.39583333 | H28: 0.39583333 | I28: 0.375 | J28: 0.375 | K28: repos | L28: repos | M28: =48 -> 48 | N28: =SUM(F28:L28)*24 -> 45 | O28: =IF(COUNTIF(PARAMETRES_REGIMES!$A$3:$A$100,$A28)>0,MIN(M28,SUM(F28:L28)*24),MIN(M28,SUM(F28:K28)*24)) -> 45 | P28: =IF(COUNTIF(PARAMETRES_REGIMES!$A$3:$A$100,$A28)>0,FLOOR(MAX(SUM(F28:L28)*24-M28,0),0.5),FLOOR(MAX(SUM(F28:K28)*24-M28,0),0.5)) -> 0 | Q28: =IF(COUNTIF(PARAMETRES_REGIMES!$A$3:$A$100,$A28)>0,0,IF(ISNUMBER(L28),FLOOR(MAX(L28*24,0),0.5),0)) -> 0 | R28: =COUNTIF(F28:L28,"ABS") -> 0 | S28: =COUNTIF(F28:L28,"Congé")+COUNTIF(F28:L28,"CSS")*0+COUNTIF(F28:L28,"CM")*0 -> 0 | T28: =COUNTIF(F28:L28,"Férié") -> 0 | U28: =O28+P28+Q28+(T28*8.5) -> 45 | V28: =IF(COUNTIF(F28:L28,"STC")>0,"STC",IF(OR(IFERROR(ISNUMBER(SEARCH("!",F28)),FALSE),IFERROR(ISNUMBER(SEARCH("!",G28)),FALSE),IFERROR(ISNUMBER(SEARCH("!",H28)),FALSE),IFERROR(ISNUMBER(SEARCH("!",I28)),FALSE),IFERROR(ISNUMBER(SEARCH("!",J28)),FALSE),IFERROR(ISNUMBER(SEARCH("!",K28)),FALSE),IFERROR(ISNUMBER(SEARCH("!",L28)),FALSE)),"À vérifier","OK")) -> OK
A29: 240 | B29: BRICHNI | C29: ZAINEB | D29: 02. Production | E29: MOD | F29: 0.39583333 | G29: ABS | H29: 0.3125 | I29: 0.39583333 | J29: 0.39583333 | K29: repos | L29: repos | M29: =48 -> 48 | N29: =SUM(F29:L29)*24 -> 36 | O29: =IF(COUNTIF(PARAMETRES_REGIMES!$A$3:$A$100,$A29)>0,MIN(M29,SUM(F29:L29)*24),MIN(M29,SUM(F29:K29)*24)) -> 36 | P29: =IF(COUNTIF(PARAMETRES_REGIMES!$A$3:$A$100,$A29)>0,FLOOR(MAX(SUM(F29:L29)*24-M29,0),0.5),FLOOR(MAX(SUM(F29:K29)*24-M29,0),0.5)) -> 0 | Q29: =IF(COUNTIF(PARAMETRES_REGIMES!$A$3:$A$100,$A29)>0,0,IF(ISNUMBER(L29),FLOOR(MAX(L29*24,0),0.5),0)) -> 0 | R29: =COUNTIF(F29:L29,"ABS") -> 1 | S29: =COUNTIF(F29:L29,"Congé")+COUNTIF(F29:L29,"CSS")*0+COUNTIF(F29:L29,"CM")*0 -> 0 | T29: =COUNTIF(F29:L29,"Férié") -> 0 | U29: =O29+P29+Q29+(T29*8.5) -> 36 | V29: =IF(COUNTIF(F29:L29,"STC")>0,"STC",IF(OR(IFERROR(ISNUMBER(SEARCH("!",F29)),FALSE),IFERROR(ISNUMBER(SEARCH("!",G29)),FALSE),IFERROR(ISNUMBER(SEARCH("!",H29)),FALSE),IFERROR(ISNUMBER(SEARCH("!",I29)),FALSE),IFERROR(ISNUMBER(SEARCH("!",J29)),FALSE),IFERROR(ISNUMBER(SEARCH("!",K29)),FALSE),IFERROR(ISNUMBER(SEARCH("!",L29)),FALSE)),"À vérifier","OK")) -> OK
A30: 242 | B30: REZGUI | C30: MAJED | D30: 02. Production | E30: MOD | F30: 0.39583333 | G30: ABS | H30: 0.3125 | I30: 0.39583333 | J30: 0.39583333 | K30: repos | L30: repos | M30: =48 -> 48 | N30: =SUM(F30:L30)*24 -> 36 | O30: =IF(COUNTIF(PARAMETRES_REGIMES!$A$3:$A$100,$A30)>0,MIN(M30,SUM(F30:L30)*24),MIN(M30,SUM(F30:K30)*24)) -> 36 | P30: =IF(COUNTIF(PARAMETRES_REGIMES!$A$3:$A$100,$A30)>0,FLOOR(MAX(SUM(F30:L30)*24-M30,0),0.5),FLOOR(MAX(SUM(F30:K30)*24-M30,0),0.5)) -> 0 | Q30: =IF(COUNTIF(PARAMETRES_REGIMES!$A$3:$A$100,$A30)>0,0,IF(ISNUMBER(L30),FLOOR(MAX(L30*24,0),0.5),0)) -> 0 | R30: =COUNTIF(F30:L30,"ABS") -> 1 | S30: =COUNTIF(F30:L30,"Congé")+COUNTIF(F30:L30,"CSS")*0+COUNTIF(F30:L30,"CM")*0 -> 0 | T30: =COUNTIF(F30:L30,"Férié") -> 0 | U30: =O30+P30+Q30+(T30*8.5) -> 36 | V30: =IF(COUNTIF(F30:L30,"STC")>0,"STC",IF(OR(IFERROR(ISNUMBER(SEARCH("!",F30)),FALSE),IFERROR(ISNUMBER(SEARCH("!",G30)),FALSE),IFERROR(ISNUMBER(SEARCH("!",H30)),FALSE),IFERROR(ISNUMBER(SEARCH("!",I30)),FALSE),IFERROR(ISNUMBER(SEARCH("!",J30)),FALSE),IFERROR(ISNUMBER(SEARCH("!",K30)),FALSE),IFERROR(ISNUMBER(SEARCH("!",L30)),FALSE)),"À vérifier","OK")) -> OK
A31: 243 | B31: LABBEN | C31: FARAH | D31: 02. Production | E31: MOD | F31: 0.39583333 | G31: 0.39583333 | H31: ABS | I31: 0.3125 | J31: 0.39583333 | K31: repos | L31: repos | M31: =48 -> 48 | N31: =SUM(F31:L31)*24 -> 36 | O31: =IF(COUNTIF(PARAMETRES_REGIMES!$A$3:$A$100,$A31)>0,MIN(M31,SUM(F31:L31)*24),MIN(M31,SUM(F31:K31)*24)) -> 36 | P31: =IF(COUNTIF(PARAMETRES_REGIMES!$A$3:$A$100,$A31)>0,FLOOR(MAX(SUM(F31:L31)*24-M31,0),0.5),FLOOR(MAX(SUM(F31:K31)*24-M31,0),0.5)) -> 0 | Q31: =IF(COUNTIF(PARAMETRES_REGIMES!$A$3:$A$100,$A31)>0,0,IF(ISNUMBER(L31),FLOOR(MAX(L31*24,0),0.5),0)) -> 0 | R31: =COUNTIF(F31:L31,"ABS") -> 1 | S31: =COUNTIF(F31:L31,"Congé")+COUNTIF(F31:L31,"CSS")*0+COUNTIF(F31:L31,"CM")*0 -> 0 | T31: =COUNTIF(F31:L31,"Férié") -> 0 | U31: =O31+P31+Q31+(T31*8.5) -> 36 | V31: =IF(COUNTIF(F31:L31,"STC")>0,"STC",IF(OR(IFERROR(ISNUMBER(SEARCH("!",F31)),FALSE),IFERROR(ISNUMBER(SEARCH("!",G31)),FALSE),IFERROR(ISNUMBER(SEARCH("!",H31)),FALSE),IFERROR(ISNUMBER(SEARCH("!",I31)),FALSE),IFERROR(ISNUMBER(SEARCH("!",J31)),FALSE),IFERROR(ISNUMBER(SEARCH("!",K31)),FALSE),IFERROR(ISNUMBER(SEARCH("!",L31)),FALSE)),"À vérifier","OK")) -> OK
A32: 244 | B32: HASNI | C32: ZAINEB | D32: 02. Production | E32: MOD | F32: ABS | G32: 0.083333333 | H32: ABS | I32: ABS | J32: ABS | K32: repos | L32: repos | M32: =48 -> 48 | N32: =SUM(F32:L32)*24 -> 2 | O32: =IF(COUNTIF(PARAMETRES_REGIMES!$A$3:$A$100,$A32)>0,MIN(M32,SUM(F32:L32)*24),MIN(M32,SUM(F32:K32)*24)) -> 2 | P32: =IF(COUNTIF(PARAMETRES_REGIMES!$A$3:$A$100,$A32)>0,FLOOR(MAX(SUM(F32:L32)*24-M32,0),0.5),FLOOR(MAX(SUM(F32:K32)*24-M32,0),0.5)) -> 0 | Q32: =IF(COUNTIF(PARAMETRES_REGIMES!$A$3:$A$100,$A32)>0,0,IF(ISNUMBER(L32),FLOOR(MAX(L32*24,0),0.5),0)) -> 0 | R32: =COUNTIF(F32:L32,"ABS") -> 4 | S32: =COUNTIF(F32:L32,"Congé")+COUNTIF(F32:L32,"CSS")*0+COUNTIF(F32:L32,"CM")*0 -> 0 | T32: =COUNTIF(F32:L32,"Férié") -> 0 | U32: =O32+P32+Q32+(T32*8.5) -> 2 | V32: =IF(COUNTIF(F32:L32,"STC")>0,"STC",IF(OR(IFERROR(ISNUMBER(SEARCH("!",F32)),FALSE),IFERROR(ISNUMBER(SEARCH("!",G32)),FALSE),IFERROR(ISNUMBER(SEARCH("!",H32)),FALSE),IFERROR(ISNUMBER(SEARCH("!",I32)),FALSE),IFERROR(ISNUMBER(SEARCH("!",J32)),FALSE),IFERROR(ISNUMBER(SEARCH("!",K32)),FALSE),IFERROR(ISNUMBER(SEARCH("!",L32)),FALSE)),"À vérifier","OK")) -> OK
A33: 247 | B33: NASRALLI | C33: THOURAYA | D33: 02. Production | E33: MOD | F33: 0.39583333 | G33: 0.39583333 | H33: 0.39583333 | I33: 0.39583333 | J33: 0.39583333 | K33: repos | L33: repos | M33: =48 -> 48 | N33: =SUM(F33:L33)*24 -> 47.5 | O33: =IF(COUNTIF(PARAMETRES_REGIMES!$A$3:$A$100,$A33)>0,MIN(M33,SUM(F33:L33)*24),MIN(M33,SUM(F33:K33)*24)) -> 47.5 | P33: =IF(COUNTIF(PARAMETRES_REGIMES!$A$3:$A$100,$A33)>0,FLOOR(MAX(SUM(F33:L33)*24-M33,0),0.5),FLOOR(MAX(SUM(F33:K33)*24-M33,0),0.5)) -> 0 | Q33: =IF(COUNTIF(PARAMETRES_REGIMES!$A$3:$A$100,$A33)>0,0,IF(ISNUMBER(L33),FLOOR(MAX(L33*24,0),0.5),0)) -> 0 | R33: =COUNTIF(F33:L33,"ABS") -> 0 | S33: =COUNTIF(F33:L33,"Congé")+COUNTIF(F33:L33,"CSS")*0+COUNTIF(F33:L33,"CM")*0 -> 0 | T33: =COUNTIF(F33:L33,"Férié") -> 0 | U33: =O33+P33+Q33+(T33*8.5) -> 47.5 | V33: =IF(COUNTIF(F33:L33,"STC")>0,"STC",IF(OR(IFERROR(ISNUMBER(SEARCH("!",F33)),FALSE),IFERROR(ISNUMBER(SEARCH("!",G33)),FALSE),IFERROR(ISNUMBER(SEARCH("!",H33)),FALSE),IFERROR(ISNUMBER(SEARCH("!",I33)),FALSE),IFERROR(ISNUMBER(SEARCH("!",J33)),FALSE),IFERROR(ISNUMBER(SEARCH("!",K33)),FALSE),IFERROR(ISNUMBER(SEARCH("!",L33)),FALSE)),"À vérifier","OK")) -> OK
A34: 248 | B34: ATTIYA | C34: NAJEH | D34: 06. RH | E34: MOI | F34: ABS | G34: 0.39583333 | H34: 0.35416667 | I34: 0.39583333 | J34: 0.39583333 | K34: repos | L34: repos | M34: =48 -> 48 | N34: =SUM(F34:L34)*24 -> 37 | O34: =IF(COUNTIF(PARAMETRES_REGIMES!$A$3:$A$100,$A34)>0,MIN(M34,SUM(F34:L34)*24),MIN(M34,SUM(F34:K34)*24)) -> 37 | P34: =IF(COUNTIF(PARAMETRES_REGIMES!$A$3:$A$100,$A34)>0,FLOOR(MAX(SUM(F34:L34)*24-M34,0),0.5),FLOOR(MAX(SUM(F34:K34)*24-M34,0),0.5)) -> 0 | Q34: =IF(COUNTIF(PARAMETRES_REGIMES!$A$3:$A$100,$A34)>0,0,IF(ISNUMBER(L34),FLOOR(MAX(L34*24,0),0.5),0)) -> 0 | R34: =COUNTIF(F34:L34,"ABS") -> 1 | S34: =COUNTIF(F34:L34,"Congé")+COUNTIF(F34:L34,"CSS")*0+COUNTIF(F34:L34,"CM")*0 -> 0 | T34: =COUNTIF(F34:L34,"Férié") -> 0 | U34: =O34+P34+Q34+(T34*8.5) -> 37 | V34: =IF(COUNTIF(F34:L34,"STC")>0,"STC",IF(OR(IFERROR(ISNUMBER(SEARCH("!",F34)),FALSE),IFERROR(ISNUMBER(SEARCH("!",G34)),FALSE),IFERROR(ISNUMBER(SEARCH("!",H34)),FALSE),IFERROR(ISNUMBER(SEARCH("!",I34)),FALSE),IFERROR(ISNUMBER(SEARCH("!",J34)),FALSE),IFERROR(ISNUMBER(SEARCH("!",K34)),FALSE),IFERROR(ISNUMBER(SEARCH("!",L34)),FALSE)),"À vérifier","OK")) -> OK
A35: 249 | B35: WERFELLI | C35: OUSSEMA | D35: 05. Logistique | E35: MOI | F35: 0.35416667 | G35: 0.35416667 | H35: 0.20833333 | I35: 0.375 | J35: 0.375 | K35: repos | L35: repos | M35: =48 -> 48 | N35: =SUM(F35:L35)*24 -> 40 | O35: =IF(COUNTIF(PARAMETRES_REGIMES!$A$3:$A$100,$A35)>0,MIN(M35,SUM(F35:L35)*24),MIN(M35,SUM(F35:K35)*24)) -> 40 | P35: =IF(COUNTIF(PARAMETRES_REGIMES!$A$3:$A$100,$A35)>0,FLOOR(MAX(SUM(F35:L35)*24-M35,0),0.5),FLOOR(MAX(SUM(F35:K35)*24-M35,0),0.5)) -> 0 | Q35: =IF(COUNTIF(PARAMETRES_REGIMES!$A$3:$A$100,$A35)>0,0,IF(ISNUMBER(L35),FLOOR(MAX(L35*24,0),0.5),0)) -> 0 | R35: =COUNTIF(F35:L35,"ABS") -> 0 | S35: =COUNTIF(F35:L35,"Congé")+COUNTIF(F35:L35,"CSS")*0+COUNTIF(F35:L35,"CM")*0 -> 0 | T35: =COUNTIF(F35:L35,"Férié") -> 0 | U35: =O35+P35+Q35+(T35*8.5) -> 40 | V35: =IF(COUNTIF(F35:L35,"STC")>0,"STC",IF(OR(IFERROR(ISNUMBER(SEARCH("!",F35)),FALSE),IFERROR(ISNUMBER(SEARCH("!",G35)),FALSE),IFERROR(ISNUMBER(SEARCH("!",H35)),FALSE),IFERROR(ISNUMBER(SEARCH("!",I35)),FALSE),IFERROR(ISNUMBER(SEARCH("!",J35)),FALSE),IFERROR(ISNUMBER(SEARCH("!",K35)),FALSE),IFERROR(ISNUMBER(SEARCH("!",L35)),FALSE)),"À vérifier","OK")) -> OK
A36: 250 | B36: EL AYEB | C36: NAOURES | D36: 06. RH | E36: MOI | F36: 0.39583333 | G36: 0.41666667 | H36: 0.41666667 | I36: 0.41666667 | J36: 0.41666667 | K36: repos | L36: repos | M36: =48 -> 48 | N36: =SUM(F36:L36)*24 -> 49.5 | O36: =IF(COUNTIF(PARAMETRES_REGIMES!$A$3:$A$100,$A36)>0,MIN(M36,SUM(F36:L36)*24),MIN(M36,SUM(F36:K36)*24)) -> 48 | P36: =IF(COUNTIF(PARAMETRES_REGIMES!$A$3:$A$100,$A36)>0,FLOOR(MAX(SUM(F36:L36)*24-M36,0),0.5),FLOOR(MAX(SUM(F36:K36)*24-M36,0),0.5)) -> 1.5 | Q36: =IF(COUNTIF(PARAMETRES_REGIMES!$A$3:$A$100,$A36)>0,0,IF(ISNUMBER(L36),FLOOR(MAX(L36*24,0),0.5),0)) -> 0 | R36: =COUNTIF(F36:L36,"ABS") -> 0 | S36: =COUNTIF(F36:L36,"Congé")+COUNTIF(F36:L36,"CSS")*0+COUNTIF(F36:L36,"CM")*0 -> 0 | T36: =COUNTIF(F36:L36,"Férié") -> 0 | U36: =O36+P36+Q36+(T36*8.5) -> 49.5 | V36: =IF(COUNTIF(F36:L36,"STC")>0,"STC",IF(OR(IFERROR(ISNUMBER(SEARCH("!",F36)),FALSE),IFERROR(ISNUMBER(SEARCH("!",G36)),FALSE),IFERROR(ISNUMBER(SEARCH("!",H36)),FALSE),IFERROR(ISNUMBER(SEARCH("!",I36)),FALSE),IFERROR(ISNUMBER(SEARCH("!",J36)),FALSE),IFERROR(ISNUMBER(SEARCH("!",K36)),FALSE),IFERROR(ISNUMBER(SEARCH("!",L36)),FALSE)),"À vérifier","OK")) -> OK
A37: 251 | B37: BRAHEM | C37: WISSEM | D37: 06. RH | E37: MOI | F37: repos | G37: 0.33333333 | H37: 0.33333333 | I37: 0.33333333 | J37: 0.33333333 | K37: repos | L37: repos | M37: =48 -> 48 | N37: =SUM(F37:L37)*24 -> 32 | O37: =IF(COUNTIF(PARAMETRES_REGIMES!$A$3:$A$100,$A37)>0,MIN(M37,SUM(F37:L37)*24),MIN(M37,SUM(F37:K37)*24)) -> 32 | P37: =IF(COUNTIF(PARAMETRES_REGIMES!$A$3:$A$100,$A37)>0,FLOOR(MAX(SUM(F37:L37)*24-M37,0),0.5),FLOOR(MAX(SUM(F37:K37)*24-M37,0),0.5)) -> 0 | Q37: =IF(COUNTIF(PARAMETRES_REGIMES!$A$3:$A$100,$A37)>0,0,IF(ISNUMBER(L37),FLOOR(MAX(L37*24,0),0.5),0)) -> 0 | R37: =COUNTIF(F37:L37,"ABS") -> 0 | S37: =COUNTIF(F37:L37,"Congé")+COUNTIF(F37:L37,"CSS")*0+COUNTIF(F37:L37,"CM")*0 -> 0 | T37: =COUNTIF(F37:L37,"Férié") -> 0 | U37: =O37+P37+Q37+(T37*8.5) -> 32 | V37: =IF(COUNTIF(F37:L37,"STC")>0,"STC",IF(OR(IFERROR(ISNUMBER(SEARCH("!",F37)),FALSE),IFERROR(ISNUMBER(SEARCH("!",G37)),FALSE),IFERROR(ISNUMBER(SEARCH("!",H37)),FALSE),IFERROR(ISNUMBER(SEARCH("!",I37)),FALSE),IFERROR(ISNUMBER(SEARCH("!",J37)),FALSE),IFERROR(ISNUMBER(SEARCH("!",K37)),FALSE),IFERROR(ISNUMBER(SEARCH("!",L37)),FALSE)),"À vérifier","OK")) -> OK
A38: 0003 | B38: JEDDA | C38: SAFA | D38: 03. Qualité | E38: MOI | F38: 0.375 | G38: 0.041666667 | H38: CM | I38: CM | J38: CM | K38: repos | L38: repos | M38: =48 -> 48 | N38: =SUM(F38:L38)*24 -> 10 | O38: =IF(COUNTIF(PARAMETRES_REGIMES!$A$3:$A$100,$A38)>0,MIN(M38,SUM(F38:L38)*24),MIN(M38,SUM(F38:K38)*24)) -> 10 | P38: =IF(COUNTIF(PARAMETRES_REGIMES!$A$3:$A$100,$A38)>0,FLOOR(MAX(SUM(F38:L38)*24-M38,0),0.5),FLOOR(MAX(SUM(F38:K38)*24-M38,0),0.5)) -> 0 | Q38: =IF(COUNTIF(PARAMETRES_REGIMES!$A$3:$A$100,$A38)>0,0,IF(ISNUMBER(L38),FLOOR(MAX(L38*24,0),0.5),0)) -> 0 | R38: =COUNTIF(F38:L38,"ABS") -> 0 | S38: =COUNTIF(F38:L38,"Congé")+COUNTIF(F38:L38,"CSS")*0+COUNTIF(F38:L38,"CM")*0 -> 0 | T38: =COUNTIF(F38:L38,"Férié") -> 0 | U38: =O38+P38+Q38+(T38*8.5) -> 10 | V38: =IF(COUNTIF(F38:L38,"STC")>0,"STC",IF(OR(IFERROR(ISNUMBER(SEARCH("!",F38)),FALSE),IFERROR(ISNUMBER(SEARCH("!",G38)),FALSE),IFERROR(ISNUMBER(SEARCH("!",H38)),FALSE),IFERROR(ISNUMBER(SEARCH("!",I38)),FALSE),IFERROR(ISNUMBER(SEARCH("!",J38)),FALSE),IFERROR(ISNUMBER(SEARCH("!",K38)),FALSE),IFERROR(ISNUMBER(SEARCH("!",L38)),FALSE)),"À vérifier","OK")) -> OK
A39: 0004 | B39: ZAIDI | C39: SEIFEDDINE | D39: 04. Maintenance | E39: MOI | F39: 0.375 | G39: 0.39583333 | H39: 0.39583333 | I39: 0.375 | J39: 0.39583333 | K39: repos | L39: repos | M39: =48 -> 48 | N39: =SUM(F39:L39)*24 -> 46.5 | O39: =IF(COUNTIF(PARAMETRES_REGIMES!$A$3:$A$100,$A39)>0,MIN(M39,SUM(F39:L39)*24),MIN(M39,SUM(F39:K39)*24)) -> 46.5 | P39: =IF(COUNTIF(PARAMETRES_REGIMES!$A$3:$A$100,$A39)>0,FLOOR(MAX(SUM(F39:L39)*24-M39,0),0.5),FLOOR(MAX(SUM(F39:K39)*24-M39,0),0.5)) -> 0 | Q39: =IF(COUNTIF(PARAMETRES_REGIMES!$A$3:$A$100,$A39)>0,0,IF(ISNUMBER(L39),FLOOR(MAX(L39*24,0),0.5),0)) -> 0 | R39: =COUNTIF(F39:L39,"ABS") -> 0 | S39: =COUNTIF(F39:L39,"Congé")+COUNTIF(F39:L39,"CSS")*0+COUNTIF(F39:L39,"CM")*0 -> 0 | T39: =COUNTIF(F39:L39,"Férié") -> 0 | U39: =O39+P39+Q39+(T39*8.5) -> 46.5 | V39: =IF(COUNTIF(F39:L39,"STC")>0,"STC",IF(OR(IFERROR(ISNUMBER(SEARCH("!",F39)),FALSE),IFERROR(ISNUMBER(SEARCH("!",G39)),FALSE),IFERROR(ISNUMBER(SEARCH("!",H39)),FALSE),IFERROR(ISNUMBER(SEARCH("!",I39)),FALSE),IFERROR(ISNUMBER(SEARCH("!",J39)),FALSE),IFERROR(ISNUMBER(SEARCH("!",K39)),FALSE),IFERROR(ISNUMBER(SEARCH("!",L39)),FALSE)),"À vérifier","OK")) -> OK
A40: 0006 | B40: ESSID | C40: HOUSSEM EDDINE | D40: 06. RH | E40: MOI | F40: 0.33333333 | G40: Repos | H40: 0.33333333 | I40: 0.33333333 | J40: 0.33333333 | K40: repos | L40: repos | M40: =48 -> 48 | N40: =SUM(F40:L40)*24 -> 32 | O40: =IF(COUNTIF(PARAMETRES_REGIMES!$A$3:$A$100,$A40)>0,MIN(M40,SUM(F40:L40)*24),MIN(M40,SUM(F40:K40)*24)) -> 32 | P40: =IF(COUNTIF(PARAMETRES_REGIMES!$A$3:$A$100,$A40)>0,FLOOR(MAX(SUM(F40:L40)*24-M40,0),0.5),FLOOR(MAX(SUM(F40:K40)*24-M40,0),0.5)) -> 0 | Q40: =IF(COUNTIF(PARAMETRES_REGIMES!$A$3:$A$100,$A40)>0,0,IF(ISNUMBER(L40),FLOOR(MAX(L40*24,0),0.5),0)) -> 0 | R40: =COUNTIF(F40:L40,"ABS") -> 0 | S40: =COUNTIF(F40:L40,"Congé")+COUNTIF(F40:L40,"CSS")*0+COUNTIF(F40:L40,"CM")*0 -> 0 | T40: =COUNTIF(F40:L40,"Férié") -> 0 | U40: =O40+P40+Q40+(T40*8.5) -> 32 | V40: =IF(COUNTIF(F40:L40,"STC")>0,"STC",IF(OR(IFERROR(ISNUMBER(SEARCH("!",F40)),FALSE),IFERROR(ISNUMBER(SEARCH("!",G40)),FALSE),IFERROR(ISNUMBER(SEARCH("!",H40)),FALSE),IFERROR(ISNUMBER(SEARCH("!",I40)),FALSE),IFERROR(ISNUMBER(SEARCH("!",J40)),FALSE),IFERROR(ISNUMBER(SEARCH("!",K40)),FALSE),IFERROR(ISNUMBER(SEARCH("!",L40)),FALSE)),"À vérifier","OK")) -> OK
...

Sheet S3_03-09_AOUT
